Workbook

Sheet EX-01 Tier Penetration
A1: EX-01 TIER PENETRATION OVERVIEW — Stores, Revenue & Density
A2: All numbers formula-linked to ⚙️ DATA. Update DATA → exhibits auto-refresh. No hardcoded numbers in exhibit cells.
A4: Tier | B4: Label | C4: Stores | D4: Stores% | E4: Revenue (₹Cr) | F4: Rev% | G4: Active Pins | H4: SPP | I4: Rev/Pin | J4: Rev/Store | K4: Status
A5: ='⚙️ DATA'!A5 | B5: ='⚙️ DATA'!B5 | C5: ='⚙️ DATA'!C5 | D5: ='⚙️ DATA'!C5/'⚙️ DATA'!C10 | E5: ='⚙️ DATA'!D5 | F5: ='⚙️ DATA'!D5/'⚙️ DATA'!D10 | G5: ='⚙️ DATA'!E5 | H5: ='⚙️ DATA'!F5 | I5: ='⚙️ DATA'!H5 | J5: ='⚙️ DATA'!G5 | K5: ⛔ SATURATING
A6: ='⚙️ DATA'!A6 | B6: ='⚙️ DATA'!B6 | C6: ='⚙️ DATA'!C6 | D6: ='⚙️ DATA'!C6/'⚙️ DATA'!C10 | E6: ='⚙️ DATA'!D6 | F6: ='⚙️ DATA'!D6/'⚙️ DATA'!D10 | G6: ='⚙️ DATA'!E6 | H6: ='⚙️ DATA'!F6 | I6: ='⚙️ DATA'!H6 | J6: ='⚙️ DATA'!G6 | K6: 🔴 HIGH
A7: ='⚙️ DATA'!A7 | B7: ='⚙️ DATA'!B7 | C7: ='⚙️ DATA'!C7 | D7: ='⚙️ DATA'!C7/'⚙️ DATA'!C10 | E7: ='⚙️ DATA'!D7 | F7: ='⚙️ DATA'!D7/'⚙️ DATA'!D10 | G7: ='⚙️ DATA'!E7 | H7: ='⚙️ DATA'!F7 | I7: ='⚙️ DATA'!H7 | J7: ='⚙️ DATA'!G7 | K7: 🟢 BENCHMARK
A8: ='⚙️ DATA'!A8 | B8: ='⚙️ DATA'!B8 | C8: ='⚙️ DATA'!C8 | D8: ='⚙️ DATA'!C8/'⚙️ DATA'!C10 | E8: ='⚙️ DATA'!D8 | F8: ='⚙️ DATA'!D8/'⚙️ DATA'!D10 | G8: ='⚙️ DATA'!E8 | H8: ='⚙️ DATA'!F8 | I8: ='⚙️ DATA'!H8 | J8: ='⚙️ DATA'!G8 | K8: 🔵 WHITESPACE
A9: ='⚙️ DATA'!A9 | B9: ='⚙️ DATA'!B9 | C9: ='⚙️ DATA'!C9 | D9: ='⚙️ DATA'!C9/'⚙️ DATA'!C10 | E9: ='⚙️ DATA'!D9 | F9: ='⚙️ DATA'!D9/'⚙️ DATA'!D10 | G9: ='⚙️ DATA'!E9 | H9: ='⚙️ DATA'!F9 | I9: ='⚙️ DATA'!H9 | J9: ='⚙️ DATA'!G9 | K9: ⚪ MICRO
A10: ='⚙️ DATA'!A10 | B10: All India | C10: ='⚙️ DATA'!C10 | D10: 100% | E10: ='⚙️ DATA'!E10 | F10: 100% | G10: ='⚙️ DATA'!G10

Sheet EX-02 Segment Mix
A1: EX-02 SEGMENT MIX — Stores, Revenue & Metro→T3 Shift (formula-driven)
A2: All stores/revenue cells = formulas from ⚙️ DATA. % cells = formula ÷ total. Amber ≥ 20%.
A4: A · STORES (formulas from ⚙️ DATA Block B)
A5: Tier | B5: Value Fashion | C5: Premium Menswear | D5: Mid Menswear | E5: Footwear | F5: Activewear | G5: Women's Ethnic | H5: Women's Western | I5: Multi/Lifestyle | J5: TOTAL
A6: ='⚙️ DATA'!A14 | B6: ='⚙️ DATA'!B14 | C6: ='⚙️ DATA'!C14 | D6: ='⚙️ DATA'!D14 | E6: ='⚙️ DATA'!E14 | F6: ='⚙️ DATA'!F14 | G6: ='⚙️ DATA'!G14 | H6: ='⚙️ DATA'!H14 | ... J6: ='⚙️ DATA'!J14
A7: ='⚙️ DATA'!A15 | B7: ='⚙️ DATA'!B15 | C7: ='⚙️ DATA'!C15 | D7: ='⚙️ DATA'!D15 | E7: ='⚙️ DATA'!E15 | F7: ='⚙️ DATA'!F15 | G7: ='⚙️ DATA'!G15 | H7: ='⚙️ DATA'!H15 | ... J7: ='⚙️ DATA'!J15
A8: ='⚙️ DATA'!A16 | B8: ='⚙️ DATA'!B16 | C8: ='⚙️ DATA'!C16 | D8: ='⚙️ DATA'!D16 | E8: ='⚙️ DATA'!E16 | F8: ='⚙️ DATA'!F16 | G8: ='⚙️ DATA'!G16 | H8: ='⚙️ DATA'!H16 | ... J8: ='⚙️ DATA'!J16
A9: ='⚙️ DATA'!A17 | B9: ='⚙️ DATA'!B17 | C9: ='⚙️ DATA'!C17 | D9: ='⚙️ DATA'!D17 | E9: ='⚙️ DATA'!E17 | F9: ='⚙️ DATA'!F17 | G9: ='⚙️ DATA'!G17 | H9: ='⚙️ DATA'!H17 | ... J9: ='⚙️ DATA'!J17
A10: ='⚙️ DATA'!A18 | B10: ='⚙️ DATA'!B18 | C10: ='⚙️ DATA'!C18 | D10: ='⚙️ DATA'!D18 | E10: ='⚙️ DATA'!E18 | F10: ='⚙️ DATA'!F18 | G10: ='⚙️ DATA'!G18 | H10: ='⚙️ DATA'!H18 | ... J10: ='⚙️ DATA'!J18
A11: ='⚙️ DATA'!A19 | B11: ='⚙️ DATA'!B19 | C11: ='⚙️ DATA'!C19 | D11: ='⚙️ DATA'!D19 | E11: ='⚙️ DATA'!E19 | F11: ='⚙️ DATA'!F19 | G11: ='⚙️ DATA'!G19 | H11: ='⚙️ DATA'!H19 | ... J11: ='⚙️ DATA'!J19
A13: B · % WITHIN TIER (formulas: each cell÷tier total from ⚙️ DATA Block D)
A14: Tier | B14: Value Fashion | C14: Premium Menswear | D14: Mid Menswear | E14: Footwear | F14: Activewear | G14: Women's Ethnic | H14: Women's Western | I14: Multi/Lifestyle
A15: ='⚙️ DATA'!A14 | B15: ='⚙️ DATA'!B32 | C15: ='⚙️ DATA'!C32 | D15: ='⚙️ DATA'!D32 | E15: ='⚙️ DATA'!E32 | F15: ='⚙️ DATA'!F32 | G15: ='⚙️ DATA'!G32 | H15: ='⚙️ DATA'!H32 | I15: ='⚙️ DATA'!I32
A16: ='⚙️ DATA'!A15 | B16: ='⚙️ DATA'!B33 | C16: ='⚙️ DATA'!C33 | D16: ='⚙️ DATA'!D33 | E16: ='⚙️ DATA'!E33 | F16: ='⚙️ DATA'!F33 | G16: ='⚙️ DATA'!G33 | H16: ='⚙️ DATA'!H33 | I16: ='⚙️ DATA'!I33
A17: ='⚙️ DATA'!A16 | B17: ='⚙️ DATA'!B34 | C17: ='⚙️ DATA'!C34 | D17: ='⚙️ DATA'!D34 | E17: ='⚙️ DATA'!E34 | F17: ='⚙️ DATA'!F34 | G17: ='⚙️ DATA'!G34 | H17: ='⚙️ DATA'!H34 | I17: ='⚙️ DATA'!I34
A18: ='⚙️ DATA'!A17 | B18: ='⚙️ DATA'!B35 | C18: ='⚙️ DATA'!C35 | D18: ='⚙️ DATA'!D35 | E18: ='⚙️ DATA'!E35 | F18: ='⚙️ DATA'!F35 | G18: ='⚙️ DATA'!G35 | H18: ='⚙️ DATA'!H35 | I18: ='⚙️ DATA'!I35
A19: ='⚙️ DATA'!A18 | B19: ='⚙️ DATA'!B36 | C19: ='⚙️ DATA'!C36 | D19: ='⚙️ DATA'!D36 | E19: ='⚙️ DATA'!E36 | F19: ='⚙️ DATA'!F36 | G19: ='⚙️ DATA'!G36 | H19: ='⚙️ DATA'!H36 | I19: ='⚙️ DATA'!I36
A22: C · REVENUE ₹Cr (formulas from ⚙️ DATA Block C)
A23: Tier | B23: Value Fashion | C23: Premium Menswear | D23: Mid Menswear | E23: Footwear | F23: Activewear | G23: Women's Ethnic | H23: Women's Western | I23: Multi/Lifestyle | J23: TOTAL
A24: ='⚙️ DATA'!A23 | B24: ='⚙️ DATA'!B23 | C24: ='⚙️ DATA'!C23 | D24: ='⚙️ DATA'!D23 | E24: ='⚙️ DATA'!E23 | F24: ='⚙️ DATA'!F23 | G24: ='⚙️ DATA'!G23 | H24: ='⚙️ DATA'!H23 | ... J24: ='⚙️ DATA'!J23
A25: ='⚙️ DATA'!A24 | B25: ='⚙️ DATA'!B24 | C25: ='⚙️ DATA'!C24 | D25: ='⚙️ DATA'!D24 | E25: ='⚙️ DATA'!E24 | F25: ='⚙️ DATA'!F24 | G25: ='⚙️ DATA'!G24 | H25: ='⚙️ DATA'!H24 | ... J25: ='⚙️ DATA'!J24
A26: ='⚙️ DATA'!A25 | B26: ='⚙️ DATA'!B25 | C26: ='⚙️ DATA'!C25 | D26: ='⚙️ DATA'!D25 | E26: ='⚙️ DATA'!E25 | F26: ='⚙️ DATA'!F25 | G26: ='⚙️ DATA'!G25 | H26: ='⚙️ DATA'!H25 | ... J26: ='⚙️ DATA'!J25
A27: ='⚙️ DATA'!A26 | B27: ='⚙️ DATA'!B26 | C27: ='⚙️ DATA'!C26 | D27: ='⚙️ DATA'!D26 | E27: ='⚙️ DATA'!E26 | F27: ='⚙️ DATA'!F26 | G27: ='⚙️ DATA'!G26 | H27: ='⚙️ DATA'!H26 | ... J27: ='⚙️ DATA'!J26
A28: ='⚙️ DATA'!A27 | B28: ='⚙️ DATA'!B27 | C28: ='⚙️ DATA'!C27 | D28: ='⚙️ DATA'!D27 | E28: ='⚙️ DATA'!E27 | F28: ='⚙️ DATA'!F27 | G28: ='⚙️ DATA'!G27 | H28: ='⚙️ DATA'!H27 | ... J28: ='⚙️ DATA'!J27
A31: D · METRO → T3 SHIFT — Stores + Revenue Signal
A32: Segment | B32: Metro% | C32: T3% | D32: Δ Store | E32: Metro Rev | F32: T3 Rev | G32: Signal | H32: Investor Read
A33: Value Fashion | B33: 17.9% | C33: 25.4% | D33: +7.5pp | E33: 6379.8 | F33: 11833.9 | G33: 🟢 RISES | H33: Tier-agnostic — rises Metro→T3
A34: Premium Menswear | B34: 28.8% | C34: 12.9% | D34: -15.9pp | E34: 2324 | F34: 691.2 | G34: 🔴 FALLS | H34: Metro luxury, T3 near-zero
A35: Mid Menswear | B35: 19.9% | C35: 23.4% | D35: +3.5pp | E35: 598.4 | F35: 1155.1 | G35: 🟡 RISES | H35: Work-casual T3 strength
A36: Footwear | B36: 26.6% | C36: 18.0% | D36: -8.6pp | E36: 2446.3 | F36: 1439.1 | G36: ⚪ STABLE | H36: Balanced — 14-18% all tiers
A37: Activewear | B37: 28.2% | C37: 14.2% | D37: -14.0pp | E37: 1605.5 | F37: 304.6 | G37: 🔴 FALLS | H37: Gym-culture urban skew
A38: Women's Ethnic | B38: 35.1% | C38: 9.4% | D38: -25.7pp | E38: 759.5 | F38: 340.3 | G38: 🔴 FALLS | H38: 74% Metro+T1, T3 whitespace
A39: Women's Western | B39: 35.2% | C39: 9.3% | D39: -25.9pp | E39: 467 | F39: 114.1 | G39: 🔴 FALLS | H39: Biggest absolute whitespace
A40: Multi/Lifestyle | B40: 23.6% | C40: 29.9% | D40: +6.3pp | E40: 6730 | F40: 3410.8 | G40: ⚪ STABLE | H40: Mall-format dependent

Sheet EX-03 Pincode Universe
A1: EX-03 PINCODE UNIVERSE — 19,000 → 3,922 Active (Revenue-Stratified)
A4: Category | B4: Pincodes | C4: Revenue (₹Cr) | D4: % of 19k | E4: Context
A5: India Serviceable Pincodes | B5: 19,000 | C5: — | D5: 100% | E5: All addressable retail pincodes
A6: Has Organised Apparel | B6: 3,922 | C6: ₹90,546 Cr | D6: 20.6% | E6: ≥1 branded store
A7: Metro Active | B7: 611 | C7: ₹21,311 Cr | D7: 3.2% | E7: 13.1 SPP | ₹34.9 Cr/pin
A8: T1 Active | B8: 679 | C8: ₹19,039 Cr | D8: 3.6% | E8: 10.8 SPP | ₹28.0 Cr/pin
A9: T2 Active | B9: 1,429 | C9: ₹27,785 Cr | D9: 7.5% | E9: 6.7 SPP | ₹19.4 Cr/pin — BENCHMARK
A10: T3 Active | B10: 1,285 | C10: ₹19,289 Cr | D10: 6.8% | E10: 4.6 SPP | ₹15.0 Cr/pin — WHITESPACE
A11: T4 Active | B11: 140 | C11: ₹3,122 Cr | D11: 0.7% | E11: Micro-markets
A12: Zero Organised Apparel | B12: 15,078 | C12: — | D12: 79.4% | E12: Unorganised — the TAM
A15: BRAND BUCKET DISTRIBUTION BY TIER + REVENUE
A16: Tier | B16: Active Pins | C16: Moat (1) | D16: Light 2-4 | E16: Comp 5-9 | F16: Crowd 10-19 | G16: Sat 20+ | H16: Revenue (₹Cr)
A17: ='⚙️ DATA'!A5 | B17: 611 | C17: 132 21.6% | D17: 162 26.5% | E17: 118 19.3% | F17: 99 16.2% | G17: 100 16.4% | H17: ='⚙️ DATA'!D5
A18: ='⚙️ DATA'!A6 | B18: 678 | C18: 190 28.0% | D18: 196 28.9% | E18: 128 18.9% | F18: 74 10.9% | G18: 90 13.3% | H18: ='⚙️ DATA'!D6
A19: ='⚙️ DATA'!A7 | B19: 1429 | C19: 563 39.4% | D19: 444 31.1% | E19: 199 13.9% | F19: 126 8.8% | G19: 97 6.8% | H19: ='⚙️ DATA'!D7
A20: ='⚙️ DATA'!A8 | B20: 1072 | C20: 429 40.0% | D20: 329 30.7% | E20: 144 13.4% | F20: 129 12.0% | G20: 41 3.8% | H20: ='⚙️ DATA'!D8
A21: ='⚙️ DATA'!A9 | B21: 140 | C21: 49 35.0% | D21: 43 30.7% | E21: 22 15.7% | F21: 12 8.6% | G21: 14 10.0% | H21: ='⚙️ DATA'!D9

Sheet EX-04 Premium Saturation
A1: EX-04 PREMIUM SATURATION — Metro Captive, T3 Near-Zero (₹ Revenue Validated)
A2: Premium = 28.8% Metro stores, ₹2,324 Cr Metro revenue. T3 = 12.9% share, ₹691 Cr. The saturation gap in ₹.
A4: PREMIUM MENSWEAR TIER BREAKDOWN
A5: Tier | B5: Stores | C5: St% | D5: Revenue (₹Cr) | E5: Rev% | F5: Rev/Store | G5: Moat Pins | H5: Moat% | I5: Coverage | J5: Signal
A6: ='⚙️ DATA'!A5 | B6: 1867 | C6: 28.8% | D6: 2324 | E6: 33.2% | F6: 1.24 | G6: 109 | H6: 36.0% | I6: 49.6% | J6: 5+ brands in 38% pins — crowded
A7: ='⚙️ DATA'!A6 | B7: 1672 | C7: 25.8% | D7: 1873.3 | E7: 26.8% | F7: 1.12 | G7: 123 | H7: 42.1% | I7: 43.0% | J7: High but still room — selective
A8: ='⚙️ DATA'!A7 | B8: 1946 | C8: 30.1% | D8: 1949 | E8: 27.8% | F8: 1 | G8: 208 | H8: 43.3% | I8: 33.6% | J8: 33% coverage — building
A9: ='⚙️ DATA'!A8 | B9: 837 | C9: 12.9% | D9: 691.2 | E9: 9.9% | F9: 0.83 | G9: 176 | H9: 52.2% | I9: 26.2% | J9: 32% coverage — wide open
A10: ='⚙️ DATA'!A9 | B10: 153 | C10: 2.4% | D10: 161.5 | E10: 2.3% | F10: 1.06 | G10: 14 | H10: 34.1% | I10: 29.3% | J10: 29% presence — micro moat
A13: ALL SEGMENTS — COVERAGE × REVENUE LEADER
A14: Segment | B14: Metro | C14: T1 | D14: T2 | E14: T3 | F14: T4 | G14: Rev Leader Tier | H14: Highest Rev (₹Cr)
A15: Value Fashion | B15: 68.4% | C15: 72.5% | D15: 74.2% | E15: 62.5% | F15: 75.0% | G15: T2 | H15: 14804.8
A16: Premium Menswear | B16: 49.6% | C16: 43.0% | D16: 33.6% | E16: 26.2% | F16: 29.3% | G16: Metro | H16: 2324
A17: Mid Menswear | B17: 44.0% | C17: 38.9% | D17: 31.8% | E17: 31.4% | F17: 44.3% | G17: T2 | H17: 1185.1
A18: Footwear | B18: 64.0% | C18: 53.6% | D18: 40.8% | E18: 33.2% | F18: 50.7% | G18: T2 | H18: 2706.9
A19: Activewear | B19: 50.4% | C19: 46.1% | D19: 31.1% | E19: 24.4% | F19: 31.4% | G19: Metro | H19: 1605.5
A20: Women's Ethnic | B20: 34.0% | C20: 24.0% | D20: 16.2% | E20: 8.2% | F20: 17.1% | G20: Metro | H20: 759.5
A21: Women's Western | B21: 36.8% | C21: 28.4% | D21: 13.2% | E21: 7.4% | F21: 9.3% | G21: Metro | H21: 467
A22: Multi/Lifestyle | B22: 39.1% | C22: 32.8% | D22: 27.3% | E22: 41.3% | F22: 26.4% | G22: Metro | H22: 6730

Sheet EX-05 VF Gateway
A1: EX-05 VALUE FASHION GATEWAY — VF Enters First, Revenue Follows
A2: T2=42% VF-only pincodes. T3=41%. VF enters, builds wallet, Premium/Mid follow within 2-3 yrs. Revenue validates.
A4: Tier | B4: Active Pins | C4: VF-Only | D4: VF-Only% | E4: Multi-Seg | F4: Multi% | G4: VF Revenue (₹Cr) | H4: VF Rev% | I4: Signal
A5: ='⚙️ DATA'!A5 | B5: 611 | C5: 141 | D5: 23.1% | E5: 177 | F5: 29.0% | G5: 6380 | H5: 15.0% | I5: 23% VF-only — graduated to multi-seg
A6: ='⚙️ DATA'!A6 | B6: 679 | C6: 225 | D6: 33.1% | E6: 169 | F6: 24.9% | G6: 7931 | H6: 18.6% | I6: 33% VF-only — transitioning
A7: ='⚙️ DATA'!A7 | B7: 1429 | C7: 602 | D7: 42.1% | E7: 255 | F7: 17.8% | G7: 14805 | H7: 34.8% | I7: 42% VF-only — THE FRONTIER. Revenue confirms wallet
A8: ='⚙️ DATA'!A8 | B8: 1285 | C8: 438 | D8: 34.1% | E8: 212 | F8: 16.5% | G8: 11834 | H8: 27.8% | I8: 41% VF-only — deeper frontier
A9: ='⚙️ DATA'!A9 | B9: 140 | C9: 52 | D9: 37.1% | E9: 29 | F9: 20.7% | G9: 1596 | H9: 3.8% | I9: 37% — micro-market
A11: VF BRAND TIER DEPTH — Revenue + Pincode Reach + Moat
A12: Brand | B12: Rev FY26 | C12: Rev/Store | D12: Metro | E12: T1 | F12: T2 | G12: T3 | H12: T4 | I12: Total Pins | J12: T2+T3+T4 | K12: Moat Pins
A13: Reliance Trends | B13: 21200 | C13: 10 | D13: 192 | E13: 281 | F13: 704 | G13: 532 | H13: 58 | I13: 1767 | J13: 1294 | K13: 792
A14: Zudio | B14: 8148 | C14: 8.46 | D14: 217 | E14: 181 | F14: 225 | G14: 132 | H14: 21 | I14: 776 | J14: 378 | K14: 182
A15: Vishal Mega Mart | B15: 5419 | C15: 6.82 | D15: 102 | E15: 118 | F15: 260 | G15: 223 | H15: 35 | I15: 738 | J15: 518 | K15: 179
A16: V Mart | B16: 2532 | C16: 5.3 | D16: 24 | E16: 97 | F16: 144 | G16: 119 | H16: 18 | I16: 402 | J16: 281 | K16: 71
A17: MBazaar | B17: 1119 | C17: 5.28 | D17: 32 | E17: 24 | F17: 45 | G17: 93 | H17: 12 | I17: 206 | J17: 150 | K17: 59
A18: Max | B18: 5007 | C18: 9.8 | D18: 102 | E18: 120 | F18: 148 | G18: 66 | H18: 12 | I18: 448 | J18: 226 | K18: 47
A19: Style Bazaar | B19: 1584 | C19: 6.02 | D19: 34 | E19: 28 | F19: 62 | G19: 95 | H19: 13 | I19: 232 | J19: 170 | K19: 29
A20: CityKart | B20: 928 | C20: 5.62 | D20: 4 | E20: 30 | F20: 49 | G20: 52 | H20: 14 | I20: 149 | J20: 115 | K20: 27
A21: CityBazaar Metro | B21: 279 | C21: 3.77 | D21: 9 | E21: 6 | F21: 16 | G21: 32 | H21: 4 | I21: 67 | J21: 52 | K21: 25
A22: V2 | B22: 3067 | C22: 9.44 | D22: 24 | E22: 50 | F22: 93 | G22: 119 | H22: 22 | I22: 308 | J22: 234 | K22: 21
A23: V Baazar | B23: 566 | C23: 4.42 | D23: 4 | E23: 13 | F23: 35 | G23: 40 | H23: 10 | I23: 102 | J23: 85 | K23: 19
A24: Easy Buy | B24: 615 | C24: 5.21 | D24: 13 | E24: 31 | F24: 50 | G24: 18 | H24: 2 | I24: 114 | J24: 70 | K24: 13

Sheet EX-06 Footwear Co-Presence
A1: EX-06 FOOTWEAR CO-PRESENCE — Leading Market Indicator + Revenue Bridge
A2: Where footwear+VF coexist, Premium arrives within 2-3 years. The organised retail sequencing playbook.
A4: Tier | B4: Footwear Pins | C4: With Premium (%) | D4: With VF (%) | E4: Both (%) | F4: VF Revenue (₹Cr) | G4: Signal
A5: ='⚙️ DATA'!A5 | B5: 391 | C5: 63.9% | D5: 72.1% | E5: 52.7% | F5: 6380 | G5: Full: 64% co-presence w/Premium
A6: ='⚙️ DATA'!A6 | B6: 364 | C6: 59.9% | D6: 77.5% | E6: 51.9% | F6: 7931 | G6: Near-complete: 60% Premium co-presence
A7: ='⚙️ DATA'!A7 | B7: 583 | C7: 58.0% | D7: 76.7% | E7: 50.1% | F7: 14805 | G7: 77% VF + 59% Prem: T2 completing
A8: ='⚙️ DATA'!A8 | B8: 426 | C8: 53.5% | D8: 77.2% | E8: 48.1% | F8: 11834 | G8: 77% VF dominant, 54% Prem following
A9: ='⚙️ DATA'!A9 | B9: 71 | C9: 46.5% | D9: 76.1% | E9: 43.7% | F9: 1596 | G9: 76% VF + 46% Prem: micro sequence

Sheet EX-07 Women's Wear
A1: EX-07 WOMEN'S WEAR — ₹944 Cr T3 vs ₹3,195 Cr Metro | Largest Revenue Whitespace
A2: Women's Ethnic + Western T3 = ₹944 Cr. Metro = ₹3,195 Cr. T3 has 60% more districts but 70% less organised revenue.
A4: Tier | B4: Ethnic Stores | C4: Ethnic Rev(₹Cr) | D4: Western Stores | E4: Western Rev(₹Cr) | F4: Combined | G4: Comb Rev | H4: Rev% of Total
A5: ='⚙️ DATA'!A5 | B5: 732 | C5: 759.5 | D5: 467 | E5: 467 | F5: 1199 | G5: 1226 | H5: 32.3%
A6: ='⚙️ DATA'!A6 | B6: 561 | C6: 606.9 | D6: 379 | E6: 362.7 | F6: 940 | G6: 970 | H6: 25.5%
A7: ='⚙️ DATA'!A7 | B7: 546 | C7: 692.4 | D7: 329 | E7: 307.1 | F7: 875 | G7: 1000 | H7: 26.3%
A8: ='⚙️ DATA'!A8 | B8: 196 | C8: 340.3 | D8: 123 | E8: 114.1 | F8: 319 | G8: 454 | H8: 12.0%
A9: ='⚙️ DATA'!A9 | B9: 52 | C9: 114.8 | D9: 30 | E9: 32.9 | F9: 82 | G9: 148 | H9: 3.9%
A12: ETHNIC BRAND TIER BREAKDOWN — Revenue + Expansion Signal
A13: Brand | B13: Rev FY26 | C13: Rev/Store | D13: Metro | E13: T1 | F13: T2 | G13: T3 | H13: T4 | I13: Total | J13: Metro+T1%
A14: Biba | B14: 381 | C14: 1.03 | D14: 123 | E14: 111 | F14: 104 | G14: 29 | H14: 3 | I14: 370 | J14: 63.2%
A15: FabIndia | B15: 1060 | C15: 3.03 | D15: 147 | E15: 85 | F15: 82 | G15: 25 | H15: 11 | I15: 350 | J15: 66.3%
A16: Manyawar | B16: 1667 | C16: 5.48 | D16: 84 | E16: 69 | F16: 87 | G16: 47 | H16: 17 | I16: 304 | J16: 50.3%
A17: W for Woman | B17: 331 | C17: 1.18 | D17: 78 | E17: 73 | F17: 87 | G17: 36 | H17: 7 | I17: 281 | J17: 53.7%
A18: Aurelia | B18: 246 | C18: 1.03 | D18: 66 | E18: 60 | F18: 72 | G18: 32 | H18: 9 | I18: 239 | J18: 52.7%
A19: Mohey | B19: 221 | C19: 1.3 | D19: 56 | E19: 53 | F19: 38 | G19: 21 | H19: 2 | I19: 170 | J19: 64.1%
A20: Soch | B20: 220 | C20: 1.33 | D20: 58 | E20: 52 | F20: 50 | G20: 3 | H20: 2 | I20: 165 | J20: 66.7%
A21: Tasva | B21: 100 | C21: 0 | D21: 47 | E21: 30 | F21: 10 | G21: 1 | H21: 0 | I21: 88 | J21: 87.5%
A22: Libas | B22: 162 | C22: 3.38 | D22: 35 | E22: 7 | F22: 6 | G22: 0 | H22: 0 | I22: 48 | J22: 87.5%
A23: Ritu Kumar | B23: 191 | C23: 4.06 | D23: 21 | E23: 16 | F23: 8 | G23: 1 | H23: 1 | I23: 47 | J23: 78.7%
A24: Global Desi | B24: 79 | C24: 3.16 | D24: 17 | E24: 5 | F24: 2 | G24: 1 | H24: 0 | I24: 25 | J24: 88.0%

Sheet EX-08 Market Fragmentation
A1: EX-08 MARKET FRAGMENTATION — 111 Brands, Revenue + Pincode Depth (→ ⚙️ DATA)
A2: Revenue FY26 + pincode reach + tier depth. Multi-tier leaders clearly visible. Ranked by FY26 revenue.
A4: # | B4: Brand | C4: Segment | D4: Rev FY26 | E4: Rev FY25 | F4: Stores | G4: Rev/Store | H4: Add FY26 | I4: Metro | J4: T1 | K4: T2 | L4: T3 | M4: T4 | N4: T2+T3+T4 | O4: Quadrant
A5: 1 | B5: Reliance Trends | C5: Value Fashion | D5: 21200 | E5: — | F5: — | G5: 10 | H5: 22526 | I5: 192 | J5: 281 | K5: 704 | L5: 532 | M5: 58 | N5: 1294 | O5: Multi-Tier Leader
A6: 2 | B6: Zudio | C6: Value Fashion | D6: 11768.9 | E6: 7597.7 | F6: 3141 | G6: — | H6: 0 | I6: 217 | J6: 181 | K6: 225 | L6: 132 | M6: 21 | N6: 378 | O6: Multi-Tier Leader
A7: 3 | B7: Westside | C7: Multi/Lifestyle | D7: 11768.9 | E7: 7597.7 | F7: 3141 | G7: — | H7: 0 | I7: 9 | J7: 0 | K7: 1 | L7: 236 | M7: 0 | N7: 237 | O7: Tier Pioneer
A8: 4 | B8: Reliance Smart Bazaar | C8: Multi/Lifestyle | D8: 11143 | E8: — | F8: — | G8: 11 | H8: 0 | I8: 141 | J8: 151 | K8: 313 | L8: 274 | M8: 31 | N8: 618 | O8: Multi-Tier Leader
A9: 5 | B9: Lifestyle | C9: Multi/Lifestyle | D9: 11083 | E9: 11573 | F9: 9133 | G9: — | H9: 0 | I9: 47 | J9: 40 | K9: 29 | L9: 4 | M9: 2 | N9: 35 | O9: Metro Fortress
A10: 6 | B10: Westside | C10: Multi/Lifestyle | D10: 8376 | E10: 6882 | F10: 300 | G10: 27.92 | H10: 52 | I10: 9 | J10: 0 | K10: 1 | L10: 236 | M10: 0 | N10: 237 | O10: Tier Pioneer
A11: 7 | B11: Zudio | C11: Value Fashion | D11: 8148 | E11: 6432 | F11: 963 | G11: 8.46 | H11: 198 | I11: 217 | J11: 181 | K11: 225 | L11: 132 | M11: 21 | N11: 378 | O11: Multi-Tier Leader
A12: 8 | B12: Arvind | C12: Premium Menswear | D12: 6836.7 | E12: 7464.2 | F12: 6412 | G12: — | H12: 0 | I12: 28 | J12: 52 | K12: 47 | L12: 37 | M12: 9 | N12: 93 | O12: Metro Fortress
A13: 9 | B13: Peter England | C13: nan | D13: 6345.3 | E13: 12352.8 | F13: 8721 | G13: — | H13: 0 | I13: 0 | J13: 0 | K13: 0 | L13: 0 | M13: 0 | N13: 0 | O13: Emerging
A14: 10 | B14: Pantaloons | C14: Multi/Lifestyle | D14: 6345.3 | E14: 12352.8 | F14: 8721 | G14: — | H14: 0 | I14: 100 | J14: 84 | K14: 104 | L14: 70 | M14: 12 | N14: 186 | O14: Multi-Tier Leader
A15: 11 | B15: Vishal Mega Mart | C15: Value Fashion | D15: 5419.4 | E15: 4499.8 | F15: 795 | G15: 6.82 | H15: 99 | I15: 102 | J15: 118 | K15: 260 | L15: 223 | M15: 35 | N15: 518 | O15: Multi-Tier Leader
A16: 12 | B16: Max | C16: Value Fashion | D16: 5007 | E16: 4316.3 | F16: — | G16: 9.8 | H16: 0 | I16: 102 | J16: 120 | K16: 148 | L16: 66 | M16: 12 | N16: 226 | O16: Multi-Tier Leader
A17: 13 | B17: Allen Solly | C17: Premium Menswear | D17: 4740 | E17: 8854 | F17: — | G17: — | H17: 0 | I17: 93 | J17: 83 | K17: 113 | L17: 47 | M17: 2 | N17: 162 | O17: Multi-Tier Leader
A18: 14 | B18: Jockey.in | C18: nan | D18: 4547.1 | E18: 4678.3 | F18: 2893 | G18: — | H18: 0 | I18: 0 | J18: 0 | K18: 0 | L18: 0 | M18: 0 | N18: 0 | O18: Emerging
A19: 15 | B19: Pantaloons | C19: Multi/Lifestyle | D19: 4247 | E19: 4196 | F19: 399 | G19: 10.64 | H19: 0 | I19: 100 | J19: 84 | K19: 104 | L19: 70 | M19: 12 | N19: 186 | O19: Multi-Tier Leader
A20: 16 | B20: DECATHLON SPORTS INDIA PRIVATE LIMITED | C20: nan | D20: 3985.6 | E20: 3894.4 | F20: 2207 | G20: — | H20: 0 | I20: 0 | J20: 0 | K20: 0 | L20: 0 | M20: 0 | N20: 0 | O20: Emerging
A21: 17 | B21: Lifestyle | C21: Multi/Lifestyle | D21: 3958.5 | E21: 3773.6 | F21: — | G21: 30.22 | H21: 0 | I21: 47 | J21: 40 | K21: 29 | L21: 4 | M21: 2 | N21: 35 | O21: Metro Fortress
A22: 18 | B22: Shoppers Stop | C22: nan | D22: 3937.9 | E22: 3705.1 | F22: 3105 | G22: — | H22: 0 | I22: 0 | J22: 0 | K22: 0 | L22: 0 | M22: 0 | N22: 0 | O22: Emerging
A23: 19 | B23: H & M HENNES & MAURITZ INDIA PRIVATE LIMITED | C23: nan | D23: 3277.2 | E23: 2941.1 | F23: — | G23: — | H23: 0 | I23: 0 | J23: 0 | K23: 0 | L23: 0 | M23: 0 | N23: 0 | O23: Emerging
A24: 20 | B24: V2 | C24: Value Fashion | D24: 3067.1 | E24: 1884.5 | F24: 325 | G24: 9.44 | H24: 136 | I24: 24 | J24: 50 | K24: 93 | L24: 119 | M24: 22 | N24: 234 | O24: Tier Pioneer
A25: 21 | B25: H&M | C25: Multi/Lifestyle | D25: 2940.5 | E25: 2803.1 | F25: — | G25: 39.74 | H25: 0 | I25: 38 | J25: 22 | K25: 10 | L25: 1 | M25: 1 | N25: 12 | O25: Emerging
A26: 22 | B26: Relaxo Footwear | C26: nan | D26: 2893.6 | E26: 2764.1 | F26: 2392 | G26: — | H26: 0 | I26: 0 | J26: 0 | K26: 0 | L26: 0 | M26: 0 | N26: 0 | O26: Emerging
A27: 23 | B27: Shoppers Stop | C27: Multi/Lifestyle | D27: 2714 | E27: 2367.1 | F27: 121 | G27: 22.43 | H27: 9 | I27: 42 | J27: 35 | K27: 30 | L27: 4 | M27: 3 | N27: 37 | O27: Emerging
A28: 24 | B28: V-Mart | C28: nan | D28: 2711.3 | E28: 2464.8 | F28: 1661 | G28: — | H28: 0 | I28: 0 | J28: 0 | K28: 0 | L28: 0 | M28: 0 | N28: 0 | O28: Emerging
A29: 25 | B29: V Mart | C29: Value Fashion | D29: 2531.5 | E29: 2177 | F29: 478 | G29: 5.3 | H29: 66 | I29: 24 | J29: 97 | K29: 144 | L29: 119 | M29: 18 | N29: 281 | O29: Multi-Tier Leader
A30: 26 | B30: Adidas | C30: Activewear | D30: 2348.7 | E30: 2084.4 | F30: — | G30: — | H30: 0 | I30: 110 | J30: 94 | K30: 110 | L30: 52 | M30: 8 | N30: 170 | O30: Multi-Tier Leader
A31: 27 | B31: Metro Brands | C31: nan | D31: 2304.5 | E31: 2070.5 | F31: 1209 | G31: — | H31: 0 | I31: 0 | J31: 0 | K31: 0 | L31: 0 | M31: 0 | N31: 0 | O31: Emerging
A32: 28 | B32: Mochi Shoes | C32: nan | D32: 2304.5 | E32: 2070.5 | F32: 1209 | G32: — | H32: 0 | I32: 0 | J32: 0 | K32: 0 | L32: 0 | M32: 0 | N32: 0 | O32: Emerging
A33: 29 | B33: Siyarams | C33: Mid Menswear | D33: 2158.2 | E33: 1885.5 | F33: — | G33: 9.34 | H33: 0 | I33: 20 | J33: 37 | K33: 64 | L33: 73 | M33: 20 | N33: 157 | O33: Tier Pioneer
A34: 30 | B34: Zara | C34: Multi/Lifestyle | D34: 2089.2 | E34: 2114.3 | F34: 25 | G34: 83.57 | H34: -1 | I34: 15 | J34: 4 | K34: 0 | L34: 0 | M34: 0 | N34: 0 | O34: Emerging
A35: 31 | B35: Decathlon | C35: Activewear | D35: 2015.2 | E35: 1643.7 | F35: — | G35: 15.87 | H35: 0 | I35: 56 | J35: 33 | K35: 31 | L35: 4 | M35: 2 | N35: 37 | O35: Metro Fortress
A36: 32 | B36: Red Tape | C36: nan | D36: 1831.8 | E36: 1458.7 | F36: — | G36: — | H36: 0 | I36: 0 | J36: 0 | K36: 0 | L36: 0 | M36: 0 | N36: 0 | O36: Emerging
A37: 33 | B37: Skechers South Asia Private Limited | C37: nan | D37: 1745.5 | E37: 1739 | F37: 659 | G37: — | H37: 0 | I37: 0 | J37: 0 | K37: 0 | L37: 0 | M37: 0 | N37: 0 | O37: Emerging
A38: 34 | B38: Marks and Spencer Reliance India | C38: nan | D38: 1742.2 | E38: 1660.1 | F38: 1041 | G38: — | H38: 0 | I38: 0 | J38: 0 | K38: 0 | L38: 0 | M38: 0 | N38: 0 | O38: Emerging
A39: 35 | B39: LEVI STRAUSS (INDIA) PRIVATE LIMITED | C39: nan | D39: 1668.7 | E39: 1615.1 | F39: — | G39: — | H39: 0 | I39: 0 | J39: 0 | K39: 0 | L39: 0 | M39: 0 | N39: 0 | O39: Emerging

Sheet EX-09 Zudio Case Study
A1: EX-09 ZUDIO — TIER EXPANSION BLUEPRINT | ₹8,148 Cr FY26 | 3,200 Store Runway
A2: 957 stores. ₹8.46 Cr/store. 23.5% of pincodes are Zudio-only (no VF competitor). 2,135 T2+T3 pincodes untouched.
A4: Tier | B4: Zudio Stores | C4: Zudio Rev (₹Cr) | D4: % of Zudio | E4: VF Seg Avg% | F4: Δ vs VF Avg | G4: Pincode Count | H4: Rev/Store | I4: Verdict
A5: ='⚙️ DATA'!A5 | B5: 288 | C5: 2452 | D5: 30.1% | E5: 17.9% | F5: +12.2pp | G5: 217 | H5: 8.46 | I5: 🚀 Over-indexed
A6: ='⚙️ DATA'!A6 | B6: 242 | C6: 2060 | D6: 25.3% | E6: 20.3% | F6: +5.0pp | G6: 181 | H6: 8.46 | I6: 🚀 Over-indexed
A7: ='⚙️ DATA'!A7 | B7: 257 | C7: 2188 | D7: 26.9% | E7: 32.9% | F7: -6.0pp | G7: 225 | H7: 8.46 | I7: ⚠️ Under
A8: ='⚙️ DATA'!A8 | B8: 147 | C8: 1252 | D8: 15.4% | E8: 25.4% | F8: -10.0pp | G8: 132 | H8: 8.46 | I8: ⚠️ Under
A9: ='⚙️ DATA'!A9 | B9: 23 | C9: 196 | D9: 2.4% | E9: 3.6% | F9: -1.2pp | G9: 21 | H9: 8.46 | I9: ✅ Aligned
A12: ZUDIO STORE POTENTIAL — ₹27,100 Cr UPSIDE VALIDATED BY PINCODE MATH
A13: Metric | B13: Value | C13: Investor Read
A14: FY26 Revenue | B14: ₹8,148 Cr | C14: 963 stores @ ₹8.46 Cr/store — Trent Annual Report FY25
A15: Current pincodes | B15: 776 total | C15: 217 Metro | 181 T1 | 225 T2 | 263 T3 | 21 T4
A16: T2 without Zudio | B16: 1,204 pincodes | C16: 79.4% of T2 active pincodes untouched — highest TAM tier
A17: T3 without Zudio | B17: 931 pincodes | C17: 87.5% of T3 active pincodes untouched — greenfield
A18: Addressable T2+T3 | B18: 2,135 pincodes | C18: At 1.5 stores/pin = 3,202 implied new Zudio stores
A19: Revenue upside (₹8.46 Cr) | B19: ₹27,100 Cr | C19: Purely T2+T3 expansion — Metro/T1 is incremental
A20: VERDICT | B20: DATA VALIDATES MANAGEMENT | C20: 3,000+ store target is supported by pincode math, not just optimism
A23: TOP CITIES — ZUDIO PRESENCE
A24: Rank | B24: City | C24: Stores | D24: % of Zudio
A25: 1 | B25: Hyderabad | C25: 63 | D25: 6.6%
A26: 2 | B26: Bengaluru | C26: 61 | D26: 6.4%
A27: 3 | B27: Delhi | C27: 43 | D27: 4.5%
A28: 4 | B28: Pune | C28: 40 | D28: 4.2%
A29: 5 | B29: Kolkata | C29: 28 | D29: 2.9%
A30: 6 | B30: Ahmedabad | C30: 27 | D30: 2.8%
A31: 7 | B31: Thane | C31: 25 | D31: 2.6%
A32: 8 | B32: Chennai | C32: 22 | D32: 2.3%
A33: 9 | B33: Surat | C33: 20 | D33: 2.1%
A34: 10 | B34: Cochin | C34: 18 | D34: 1.9%
A35: 11 | B35: Kozhikode | C35: 18 | D35: 1.9%
A36: 12 | B36: Jaipur | C36: 17 | D36: 1.8%
... A39: 15 | B39: Vadodara | C39: 14 | D39: 1.5%

Sheet EX-10 Global Comparison
A1: EX-10 INDIA vs GLOBAL — Density Convergence Thesis (China 2003 Analog)
A4: Market | B4: Population (Mn) | C4: Stores | D4: People/Store | E4: Revenue | F4: Stage | G4: India Tier Analog
A5: USA | B5: 331 | C5: 415,000 | D5: 800 | E5: — | F5: Mature | G5: —
A6: UK | B6: 67 | C6: 60,000 | D6: 1,117 | E6: — | F6: Mature | G6: —
A7: China | B7: 1,440 | C7: 850,000 | D7: 1,694 | E7: — | F7: Growing Fast | G7: —
A8: India Total | B8: 1,380 | C8: 31,813 | D8: 43,341 | E8: ₹90,546 Cr total | F8: Early Stage | G8: All Tiers
A9: India Metro | B9: 87 | C9: 8,002 | D9: 10,880 | E9: ₹21,311 Cr / 611 pins | F9: Near China 2020 | G9: China 2020
A10: India T1 | B10: 110 | C10: 7,340 | D10: 15,000 | E10: ₹19,039 Cr / 679 pins | F10: China 2015 | G10: China 2015
A11: India T2 | B11: 345 | C11: 9,518 | D11: 36,262 | E11: ₹27,785 Cr / 1,429 pins — BENCHMARK | F11: Early China 2010 | G11: China 2010
A12: India T3 | B12: 700 | C12: 5,963 | D12: 117,345 | E12: ₹19,289 Cr / 1,285 pins — WHITESPACE | F12: Pre-organised | G12: China 2003

Sheet EX-11 Brand×Tier Heatmap
A1: EX-11 BRAND × TIER HEATMAP — Revenue + Pincode Depth (colour = relative depth)
A2: Darker cell = deeper penetration vs category leader. Ranked by FY26 revenue.
A4: # | B4: Brand | C4: Segment | D4: Rev FY26 | E4: Rev/Store | F4: Metro | G4: T1 | H4: T2 | I4: T3 | J4: T4 | K4: Total Pins | L4: T2+T3+T4 | M4: Quadrant
A5: 1 | B5: Reliance Trends | C5: Value Fashion | D5: 21200 | E5: 10 | F5: 192 | G5: 281 | H5: 704 | I5: 532 | J5: 58 | K5: 1767 | L5: 1294 | M5: Multi-Tier Leader
A6: 2 | B6: Zudio | C6: Value Fashion | D6: 11768.9 | E6: — | F6: 217 | G6: 181 | H6: 225 | I6: 132 | J6: 21 | K6: 776 | L6: 378 | M6: Multi-Tier Leader
A7: 3 | B7: Westside | C7: Multi/Lifestyle | D7: 11768.9 | E7: — | F7: 9 | G7: 0 | H7: 1 | I7: 236 | J7: 0 | K7: 246 | L7: 237 | M7: Tier Pioneer
A8: 4 | B8: Reliance Smart Bazaar | C8: Multi/Lifestyle | D8: 11143 | E8: 11 | F8: 141 | G8: 151 | H8: 313 | I8: 274 | J8: 31 | K8: 910 | L8: 618 | M8: Multi-Tier Leader
A9: 5 | B9: Lifestyle | C9: Multi/Lifestyle | D9: 11083 | E9: — | F9: 47 | G9: 40 | H9: 29 | I9: 4 | J9: 2 | K9: 122 | L9: 35 | M9: Metro Fortress
A10: 6 | B10: Westside | C10: Multi/Lifestyle | D10: 8376 | E10: 27.92 | F10: 9 | G10: 0 | H10: 1 | I10: 236 | J10: 0 | K10: 246 | L10: 237 | M10: Tier Pioneer
A11: 7 | B11: Zudio | C11: Value Fashion | D11: 8148 | E11: 8.46 | F11: 217 | G11: 181 | H11: 225 | I11: 132 | J11: 21 | K11: 776 | L11: 378 | M11: Multi-Tier Leader
A12: 8 | B12: Arvind | C12: Premium Menswear | D12: 6836.7 | E12: — | F12: 28 | G12: 52 | H12: 47 | I12: 37 | J12: 9 | K12: 173 | L12: 93 | M12: Metro Fortress
A13: 9 | B13: Peter England | C13: nan | D13: 6345.3 | E13: — | F13: 0 | G13: 0 | H13: 0 | I13: 0 | J13: 0 | K13: 0 | L13: 0 | M13: Emerging
A14: 10 | B14: Pantaloons | C14: Multi/Lifestyle | D14: 6345.3 | E14: — | F14: 100 | G14: 84 | H14: 104 | I14: 70 | J14: 12 | K14: 370 | L14: 186 | M14: Multi-Tier Leader
A15: 11 | B15: Vishal Mega Mart | C15: Value Fashion | D15: 5419.4 | E15: 6.82 | F15: 102 | G15: 118 | H15: 260 | I15: 223 | J15: 35 | K15: 738 | L15: 518 | M15: Multi-Tier Leader
A16: 12 | B16: Max | C16: Value Fashion | D16: 5007 | E16: 9.8 | F16: 102 | G16: 120 | H16: 148 | I16: 66 | J16: 12 | K16: 448 | L16: 226 | M16: Multi-Tier Leader
A17: 13 | B17: Allen Solly | C17: Premium Menswear | D17: 4740 | E17: — | F17: 93 | G17: 83 | H17: 113 | I17: 47 | J17: 2 | K17: 338 | L17: 162 | M17: Multi-Tier Leader
A18: 14 | B18: Jockey.in | C18: nan | D18: 4547.1 | E18: — | F18: 0 | G18: 0 | H18: 0 | I18: 0 | J18: 0 | K18: 0 | L18: 0 | M18: Emerging
A19: 15 | B19: Pantaloons | C19: Multi/Lifestyle | D19: 4247 | E19: 10.64 | F19: 100 | G19: 84 | H19: 104 | I19: 70 | J19: 12 | K19: 370 | L19: 186 | M19: Multi-Tier Leader
A20: 16 | B20: DECATHLON SPORTS INDIA PRIVATE LIMITED | C20: nan | D20: 3985.6 | E20: — | F20: 0 | G20: 0 | H20: 0 | I20: 0 | J20: 0 | K20: 0 | L20: 0 | M20: Emerging
A21: 17 | B21: Lifestyle | C21: Multi/Lifestyle | D21: 3958.5 | E21: 30.22 | F21: 47 | G21: 40 | H21: 29 | I21: 4 | J21: 2 | K21: 122 | L21: 35 | M21: Metro Fortress
A22: 18 | B22: Shoppers Stop | C22: nan | D22: 3937.9 | E22: — | F22: 0 | G22: 0 | H22: 0 | I22: 0 | J22: 0 | K22: 0 | L22: 0 | M22: Emerging
A23: 19 | B23: H & M HENNES & MAURITZ INDIA PRIVATE LIMITED | C23: nan | D23: 3277.2 | E23: — | F23: 0 | G23: 0 | H23: 0 | I23: 0 | J23: 0 | K23: 0 | L23: 0 | M23: Emerging
A24: 20 | B24: V2 | C24: Value Fashion | D24: 3067.1 | E24: 9.44 | F24: 24 | G24: 50 | H24: 93 | I24: 119 | J24: 22 | K24: 308 | L24: 234 | M24: Tier Pioneer
A25: 21 | B25: H&M | C25: Multi/Lifestyle | D25: 2940.5 | E25: 39.74 | F25: 38 | G25: 22 | H25: 10 | I25: 1 | J25: 1 | K25: 72 | L25: 12 | M25: Emerging
A26: 22 | B26: Relaxo Footwear | C26: nan | D26: 2893.6 | E26: — | F26: 0 | G26: 0 | H26: 0 | I26: 0 | J26: 0 | K26: 0 | L26: 0 | M26: Emerging
A27: 23 | B27: Shoppers Stop | C27: Multi/Lifestyle | D27: 2714 | E27: 22.43 | F27: 42 | G27: 35 | H27: 30 | I27: 4 | J27: 3 | K27: 114 | L27: 37 | M27: Emerging
A28: 24 | B28: V-Mart | C28: nan | D28: 2711.3 | E28: — | F28: 0 | G28: 0 | H28: 0 | I28: 0 | J28: 0 | K28: 0 | L28: 0 | M28: Emerging
A29: 25 | B29: V Mart | C29: Value Fashion | D29: 2531.5 | E29: 5.3 | F29: 24 | G29: 97 | H29: 144 | I29: 119 | J29: 18 | K29: 402 | L29: 281 | M29: Multi-Tier Leader
A30: 26 | B30: Adidas | C30: Activewear | D30: 2348.7 | E30: — | F30: 110 | G30: 94 | H30: 110 | I30: 52 | J30: 8 | K30: 374 | L30: 170 | M30: Multi-Tier Leader
A31: 27 | B31: Metro Brands | C31: nan | D31: 2304.5 | E31: — | F31: 0 | G31: 0 | H31: 0 | I31: 0 | J31: 0 | K31: 0 | L31: 0 | M31: Emerging
A32: 28 | B32: Mochi Shoes | C32: nan | D32: 2304.5 | E32: — | F32: 0 | G32: 0 | H32: 0 | I32: 0 | J32: 0 | K32: 0 | L32: 0 | M32: Emerging
A33: 29 | B33: Siyarams | C33: Mid Menswear | D33: 2158.2 | E33: 9.34 | F33: 20 | G33: 37 | H33: 64 | I33: 73 | J33: 20 | K33: 214 | L33: 157 | M33: Tier Pioneer
A34: 30 | B34: Zara | C34: Multi/Lifestyle | D34: 2089.2 | E34: 83.57 | F34: 15 | G34: 4 | H34: 0 | I34: 0 | J34: 0 | K34: 19 | L34: 0 | M34: Emerging
A35: 31 | B35: Decathlon | C35: Activewear | D35: 2015.2 | E35: 15.87 | F35: 56 | G35: 33 | H35: 31 | I35: 4 | J35: 2 | K35: 126 | L35: 37 | M35: Metro Fortress
A36: 32 | B36: Red Tape | C36: nan | D36: 1831.8 | E36: — | F36: 0 | G36: 0 | H36: 0 | I36: 0 | J36: 0 | K36: 0 | L36: 0 | M36: Emerging
A37: 33 | B37: Skechers South Asia Private Limited | C37: nan | D37: 1745.5 | E37: — | F37: 0 | G37: 0 | H37: 0 | I37: 0 | J37: 0 | K37: 0 | L37: 0 | M37: Emerging
A38: 34 | B38: Marks and Spencer Reliance India | C38: nan | D38: 1742.2 | E38: — | F38: 0 | G38: 0 | H38: 0 | I38: 0 | J38: 0 | K38: 0 | L38: 0 | M38: Emerging
A39: 35 | B39: LEVI STRAUSS (INDIA) PRIVATE LIMITED | C39: nan | D39: 1668.7 | E39: — | F39: 0 | G39: 0 | H39: 0 | I39: 0 | J39: 0 | K39: 0 | L39: 0 | M39: Emerging
A40: 36 | B40: Manyawar | C40: Women's Ethnic | D40: 1666.7 | E40: 5.48 | F40: 77 | G40: 62 | H40: 80 | I40: 45 | J40: 13 | K40: 277 | L40: 138 | M40: Metro Fortress
A41: 37 | B41: Puma | C41: Activewear | D41: 1618.3 | E41: 4.05 | F41: 115 | G41: 89 | H41: 107 | I41: 35 | J41: 12 | K41: 358 | L41: 154 | M41: Multi-Tier Leader
...

Sheet EX-12 Segment Geo Reach
A1: EX-12 SEGMENT GEOGRAPHIC REACH — Pincode Depth + Revenue Per Tier
A4: Segment | B4: Metro Pins | C4: T1 | D4: T2 | E4: T3 | F4: T4 | G4: Total Pins | H4: T2+T3+T4 | I4: Metro Rev | J4: T3 Rev | K4: T3/Metro Ratio | L4: Metro Dep%
A5: Value Fashion | B5: 418 | C5: 492 | D5: 1061 | E5: 803 | F5: 105 | G5: 2879 | H5: 1969 | I5: 6379.8 | J5: 11833.9 | K5: 1.85x | L5: 31.6%
A6: Premium Menswear | B6: 303 | C6: 292 | D6: 480 | E6: 337 | F6: 41 | G6: 1453 | H6: 858 | I6: 2324 | J6: 691.2 | K6: 0.30x | L6: 40.9%
A7: Mid Menswear | B7: 269 | C7: 264 | D7: 454 | E7: 403 | F7: 62 | G7: 1452 | H7: 919 | I7: 598.4 | J7: 1155.1 | K7: 1.93x | L7: 36.7%
A8: Footwear | B8: 391 | C8: 364 | D8: 583 | E8: 426 | F8: 71 | G8: 1835 | H8: 1080 | I8: 2446.3 | J8: 1439.1 | K8: 0.59x | L8: 41.1%
A9: Activewear | B9: 308 | C9: 313 | D9: 444 | E9: 313 | F9: 44 | G9: 1422 | H9: 801 | I9: 1605.5 | J9: 304.6 | K9: 0.19x | L9: 43.7%
A10: Women's Ethnic | B10: 208 | C10: 163 | D10: 231 | E10: 106 | F10: 24 | G10: 732 | H10: 361 | I10: 759.5 | J10: 340.3 | K10: 0.45x | L10: 50.7%
A11: Women's Western | B11: 225 | C11: 193 | D11: 189 | E11: 95 | F11: 13 | G11: 715 | H11: 297 | I11: 467 | J11: 114.1 | K11: 0.24x | L11: 58.5%
A12: Multi/Lifestyle | B12: 239 | C12: 223 | D12: 390 | E12: 531 | F12: 37 | G12: 1420 | H12: 958 | I12: 6730 | J12: 3410.8 | K12: 0.51x | L12: 32.5%

Sheet EX-13 White Space
A1: EX-13 WHITE SPACE OPPORTUNITY — Revenue-Weighted Priority Map
A4: Priority | B4: Description | C4: Revenue Potential | D4: Examples
A5: 🟢 HIGH: T2 Underserved | B5: T2 cities with <5 stores but high income | C5: ₹5-15 Cr wallet/pin | D5: Jodhpur, Udaipur, Rajkot cluster
A6: 🟡 MEDIUM: T3 Near-T2 | B6: T3 cities near T1 — VF present, Premium absent | C6: ₹3-8 Cr wallet/pin | D6: District HQs near T1 cities
A7: 🔵 LONG: T3 Greenfield | B7: Zero organised — 5-10yr option value | C7: 688 zero T3 pincodes | D7: ~322 districts, bulk of 15k zeros
A8: 🔴 AVOID: Metro Saturated | B8: 5+ brands, Premium-heavy pincodes | C8: Negative ROI for new entrants | D8: South Mumbai, CP Delhi, Koregaon Park
A11: TOP UNDERSERVED T2 CITIES — Low Stores, Revenue Whitespace
A12: Rank | B12: City | C12: Stores | D12: Revenue (₹Cr) | E12: Rev/Pin | F12: Whitespace Score
A13: 1 | B13: Wapi | C13: 1 | D13: 10 | E13: 10 | F13: 500
A14: 2 | B14: Silvassa | C14: 2 | D14: 1.8 | E14: 1.8 | F14: 333
A15: 3 | B15: Barmer | C15: 11 | D15: 30.6 | E15: 15.3 | F15: 83
A16: 4 | B16: Raj-Nandgaon | C16: 11 | D16: 20.1 | E16: 10.1 | F16: 83
A17: 5 | B17: Jalna | C17: 12 | D17: 33.6 | E17: 11.2 | F17: 77
A18: 6 | B18: Korba | C18: 14 | D18: 43.5 | E18: 21.8 | F18: 67
A19: 7 | B19: Dumka | C19: 14 | D19: 58.8 | E19: 29.4 | F19: 67
A20: 8 | B20: Pali | C20: 15 | D20: 26.8 | E20: 13.4 | F20: 62
A21: 9 | B21: Mainpuri | C21: 16 | D21: 59.2 | E21: 29.6 | F21: 59
A22: 10 | B22: Raigarh | C22: 17 | D22: 55.2 | E22: 27.6 | F22: 56
A23: 11 | B23: Unnao | C23: 17 | D23: 46.3 | E23: 15.4 | F23: 56
A24: 12 | B24: Guna | C24: 17 | D24: 52.3 | E24: 52.3 | F24: 56
... A32: 20 | B32: Banda | C32: 26 | D32: 70.8 | E32: 10.1 | F32: 37

Sheet EX-14 Investor Narrative
A1: EX-14 BERNSTEIN INVESTOR NARRATIVE — Revenue-Validated Pitch
A3: ONE-LINE THESIS
A4: India's ₹90,546 Cr organised apparel story is not penetration — it is TIER CONVERGENCE. Metro crowded at ₹34.9 Cr/pin. T2 at ₹19.4 Cr/pin is the benchmark. T3 at ₹15 Cr/pin is the decade-long option. China 2003 analog → 8-12% CAGR for multi-tier leaders.
A6: SIGNAL 1 — METRO SATURATING (₹21,311 Cr, 611 pins)
A7: ₹34.9 Cr/pin. Premium = 28.8% Metro stores, ₹2,324 Cr. 5+ brands compete in 37% of premium pincodes. Revenue-per-store getting split. Incremental Metro openings face diminishing returns — wrong capex allocation.
A9: SIGNAL 2 — T2 = SCALE + RUNWAY (₹27,785 Cr, 1,429 pins)
A10: Most stores (9,518) + most revenue (₹27,785 Cr) — yet ₹19.4 Cr/pin vs Metro ₹34.9 Cr/pin. 44% under-monetised per pincode. 147 cities. First-mover window is 2-4 years. Revenue density gap IS the investment thesis.
A12: SIGNAL 3 — ZUDIO 3,000+ STORES: DATA VALIDATED (₹27,100 Cr UPSIDE)
A13: FY26 = ₹8,148 Cr, ₹8.46 Cr/store. 2,135 T2+T3 pincodes untouched. At 1.5 stores/pin × ₹8.46 Cr = ₹27,100 Cr. Management 3,000+ target is CONSERVATIVE when validated against pincode math.
A15: SIGNAL 4 — WOMEN'S WEAR: ₹944 Cr T3 vs ₹3,195 Cr METRO
A16: 38% women's wallet in T3 HH spend is almost entirely unorganised. Revenue gap 3.4×. Go Colors: ₹609 Cr, 473 moat pins — no T3 WW competitor. Category revenue runway is 5-10× current organised base.
A18: SIGNAL 5 — MULTI-TIER LEADERS IDENTIFIABLE (Revenue Moat)
... A22: India T3 at ₹15 Cr/pin = China 2003. If T3 converges to T2 (₹19.4 Cr/pin): 1,285 pins × ₹4.4 Cr uplift = ₹5,654 Cr incremental revenue on current active pins alone. Plus 688 zero-pincodes activating adds ₹8,000-12,000 Cr over 10 years.

Sheet ⚙️ DATA
A1: ⚙️ DATA — Master Source Table | Update here → all exhibits auto-refresh via formulas
A3: A — TIER SUMMARY
A4: Tier | B4: Label | C4: Stores | D4: Revenue_Cr | E4: Active_Pins | F4: SPP | G4: Rev_per_Store | H4: Rev_per_Pin | I4: Stores_%
A5: Metro | B5: Mega Metro | C5: 8002 | D5: 21310.5 | E5: 611 | F5: 13.1 | G5: 2.66 | H5: 34.88 | I5: =C5/C10
A6: T1 | B6: Tier 1 City | C6: 7340 | D6: 19039.1 | E6: 679 | F6: 10.81 | G6: 2.59 | H6: 28.04 | I6: =C6/C10
A7: T2 | B7: Tier 2 City | C7: 9518 | D7: 27785.4 | E7: 1429 | F7: 6.66 | G7: 2.92 | H7: 19.44 | I7: =C7/C10
A8: T3 | B8: Tier 3 Town | C8: 5963 | D8: 19289.1 | E8: 1285 | F8: 4.64 | G8: 3.23 | H8: 15.01 | I8: =C8/C10
A9: T4 | B9: Tier 4 Micro | C9: 990 | D9: 3122.2 | E9: 140 | F9: 7.07 | G9: 3.15 | H9: 22.3 | I9: =C9/C10
A10: TOTAL | B10: All India | C10: =SUM(C5:C9) | D10: =SUM(D5:D9) | E10: =SUM(E5:E9) | F10: =C10/E10 | G10: =D10/C10 | H10: =D10/E10 | I10: 100.0%
A12: B — STORES by Tier × Segment
A13: Tier | B13: Value Fashion | C13: Premium Menswear | D13: Mid Menswear | E13: Footwear | F13: Activewear | G13: Women's Ethnic | H13: Women's Western | I13: Multi/Lifestyle | J13: TOTAL
A14: Metro | B14: 1234 | C14: 1867 | D14: 835 | E14: 1400 | F14: 953 | G14: 732 | H14: 467 | I14: 514 | J14: =SUM(B14:I14)
A15: T1 | B15: 1403 | C15: 1672 | D15: 867 | E15: 1171 | F15: 880 | G15: 561 | H15: 379 | I15: 407 | J15: =SUM(B15:I15)
A16: T2 | B16: 2269 | C16: 1946 | D16: 1337 | E16: 1563 | F16: 981 | G16: 546 | H16: 329 | I16: 547 | J16: =SUM(B16:I16)
A17: T3 | B17: 1751 | C17: 837 | D17: 981 | E17: 945 | F17: 479 | G17: 196 | H17: 123 | I17: 651 | J17: =SUM(B17:I17)
A18: T4 | B18: 250 | C18: 153 | D18: 178 | E18: 180 | F18: 92 | G18: 52 | H18: 30 | I18: 55 | J18: =SUM(B18:I18)
A19: TOTAL | B19: =SUM(B14:B18) | C19: =SUM(C14:C18) | D19: =SUM(D14:D18) | E19: =SUM(E14:E18) | F19: =SUM(F14:F18) | G19: =SUM(G14:G18) | H19: =SUM(H14:H18) | I19: =SUM(I14:I18) | J19: =SUM(J14:J18)
A21: C — REVENUE by Tier × Segment (₹ Cr)
A22: Tier | B22: Value Fashion | C22: Premium Menswear | D22: Mid Menswear | E22: Footwear | F22: Activewear | G22: Women's Ethnic | H22: Women's Western | I22: Multi/Lifestyle | J22: TOTAL
A23: Metro | B23: 6379.8 | C23: 2324 | D23: 598.4 | E23: 2446.3 | F23: 1605.5 | G23: 759.5 | H23: 467 | I23: 6730 | J23: =SUM(B23:I23)
A24: T1 | B24: 7930.6 | C24: 1873.3 | D24: 756.1 | E24: 1985 | F24: 1074.6 | G24: 606.9 | H24: 362.7 | I24: 4450 | J24: =SUM(B24:I24)
A25: T2 | B25: 14804.8 | C25: 1949 | D25: 1185.1 | E25: 2706.9 | F25: 961.1 | G25: 692.4 | H25: 307.1 | I25: 5178.9 | J25: =SUM(B25:I25)
A26: T3 | B26: 11833.9 | C26: 691.2 | D26: 1155.1 | E26: 1439.1 | F26: 304.6 | G26: 340.3 | H26: 114.1 | I26: 3410.8 | J26: =SUM(B26:I26)
A27: T4 | B27: 1596.2 | C27: 161.5 | D27: 290.9 | E27: 310.3 | F27: 92.6 | G27: 114.8 | H27: 32.9 | I27: 523.1 | J27: =SUM(B27:I27)
A28: TOTAL | B28: =SUM(B23:B27) | C28: =SUM(C23:C27) | D28: =SUM(D23:D27) | E28: =SUM(E23:E27) | F28: =SUM(F23:F27) | G28: =SUM(G23:G27) | H28: =SUM(H23:H27) | I28: =SUM(I23:I27) | J28: =SUM(J23:J27)
A30: D — SEGMENT % WITHIN TIER (formulas → Block B)
A31: Tier | B31: Value Fashion | C31: Premium Menswear | D31: Mid Menswear | E31: Footwear | F31: Activewear | G31: Women's Ethnic | H31: Women's Western | I31: Multi/Lifestyle
A32: Metro | B32: =IF(J14=0,0,B14/J14) | C32: =IF(J14=0,0,C14/J14) | D32: =IF(J14=0,0,D14/J14) | E32: =IF(J14=0,0,E14/J14) | F32: =IF(J14=0,0,F14/J14) | G32: =IF(J14=0,0,G14/J14) | H32: =IF(J14=0,0,H14/J14) | I32: =IF(J14=0,0,I14/J14)
A33: T1 | B33: =IF(J15=0,0,B15/J15) | C33: =IF(J15=0,0,C15/J15) | D33: =IF(J15=0,0,D15/J15) | E33: =IF(J15=0,0,E15/J15) | F33: =IF(J15=0,0,F15/J15) | G33: =IF(J15=0,0,G15/J15) | H33: =IF(J15=0,0,H15/J15) | I33: =IF(J15=0,0,I15/J15)
A34: T2 | B34: =IF(J16=0,0,B16/J16) | C34: =IF(J16=0,0,C16/J16) | D34: =IF(J16=0,0,D16/J16) | E34: =IF(J16=0,0,E16/J16) | F34: =IF(J16=0,0,F16/J16) | G34: =IF(J16=0,0,G16/J16) | H34: =IF(J16=0,0,H16/J16) | I34: =IF(J16=0,0,I16/J16)
A35: T3 | B35: =IF(J17=0,0,B17/J17) | C35: =IF(J17=0,0,C17/J17) | D35: =IF(J17=0,0,D17/J17) | E35: =IF(J17=0,0,E17/J17) | F35: =IF(J17=0,0,F17/J17) | G35: =IF(J17=0,0,G17/J17) | H35: =IF(J17=0,0,H17/J17) | I35: =IF(J17=0,0,I17/J17)
A36: T4 | B36: =IF(J18=0,0,B18/J18) | C36: =IF(J18=0,0,C18/J18) | D36: =IF(J18=0,0,D18/J18) | E36: =IF(J18=0,0,E18/J18) | F36: =IF(J18=0,0,F18/J18) | G36: =IF(J18=0,0,G18/J18) | H36: =IF(J18=0,0,H18/J18) | I36: =IF(J18=0,0,I18/J18)
A38: E — BRAND FINANCIALS (FY25/26 actual — update here to refresh exhibits)
A39: Brand | B39: Segment | C39: Rev FY26 | D39: Rev FY25 | E39: Stores Mar26 | F39: Rev/Store | G39: Store Adds FY25 | H39: Store Adds FY26 | I39: Metro Pins | J39: T1 Pins | K39: T2 Pins | L39: T3 Pins
A40: Reliance_Trends | B40: Value Fashion | C40: 21200 | D40: 0 | E40: 0 | F40: 10 | G40: 2022 | H40: 22526 | I40: 192 | J40: 281 | K40: 704 | L40: 532
A41: Zudio | B41: Value Fashion | C41: 11768.88 | D41: 7597.7 | E41: 3141 | F41: 0 | G41: 0 | H41: 0 | I41: 217 | J41: 181 | K41: 225 | L41: 132
A42: Westside | B42: Multi/Lifestyle | C42: 11768.88 | D42: 7597.7 | E42: 3141 | F42: 0 | G42: 0 | H42: 0 | I42: 9 | J42: 0 | K42: 1 | L42: 236
A43: Reliance_Smart_Bazaar | B43: Multi/Lifestyle | C43: 11143 | D43: 0 | E43: 0 | F43: 11 | G43: 0 | H43: 0 | I43: 141 | J43: 151 | K43: 313 | L43: 274
A44: Lifestyle | B44: Multi/Lifestyle | C44: 11083 | D44: 11573 | E44: 9133 | F44: 0 | G44: 43 | H44: 0 | I44: 47 | J44: 40 | K44: 29 | L44: 4
A45: Westside | B45: Multi/Lifestyle | C45: 8376 | D45: 6882 | E45: 300 | F45: 27.92 | G45: 16 | H45: 52 | I45: 9 | J45: 0 | K45: 1 | L45: 236
...
