Workbook

Sheet EX-15 VF vs Premium
A1: EX-15 VF vs PREMIUM vs MID — The Tier Divergence Chart
A2: VF rises +7.5pp Metro→T3. Premium falls -15.9pp. Revenue tells the same story in ₹ Cr. This IS the investment thesis.
A4: A · STORE % WITHIN TIER (formulas from ⚙️ DATA Block D)
A5: Segment | B5: Metro% | C5: T1% | D5: T2% | E5: T3% | F5: T4% | G5: Metro+T1 | H5: T2+T3+T4 | I5: Δ Metro→T3 | J5: Signal
A6: Value Fashion | B6: 17.9% | C6: 20.3% | D6: 32.9% | E6: 25.4% | F6: 3.6% | G6: 38.2% | H6: 61.9% | I6: +7.5pp | J6: 🟢 RISES — tier-agnostic entry brand
A7: Premium Menswear | B7: 28.8% | C7: 25.8% | D7: 30.1% | E7: 12.9% | F7: 2.4% | G7: 54.6% | H7: 45.4% | I7: -15.9pp | J7: 🔴 FALLS — Metro luxury, T3 near-zero
A8: Mid Menswear | B8: 19.9% | C8: 20.7% | D8: 31.8% | E8: 23.4% | F8: 4.2% | G8: 40.6% | H8: 59.4% | I8: +3.5pp | J8: 🟡 RISES — work-casual crossover
A9: Footwear | B9: 26.6% | C9: 22.3% | D9: 29.7% | E9: 18.0% | F9: 3.4% | G9: 48.9% | H9: 51.1% | I9: -8.6pp | J9: ⚪ STABLE — most balanced category
A10: Activewear | B10: 28.2% | C10: 26.0% | D10: 29.0% | E10: 14.2% | F10: 2.7% | G10: 54.2% | H10: 45.9% | I10: -14.0pp | J10: 🔴 FALLS — urban aspirational skew
A11: Women's Ethnic | B11: 35.1% | C11: 26.9% | D11: 26.2% | E11: 9.4% | F11: 2.5% | G11: 62.0% | H11: 38.1% | I11: -25.7pp | J11: 🔴 FALLS — Metro captive, T3 whitespace
A12: Women's Western | B12: 35.2% | C12: 28.5% | D12: 24.8% | E12: 9.3% | F12: 2.3% | G12: 63.7% | H12: 36.4% | I12: -25.9pp | J12: 🔴 FALLS — largest absolute whitespace
A13: Multi/Lifestyle | B13: 23.6% | C13: 18.7% | D13: 25.2% | E13: 29.9% | F13: 2.5% | G13: 42.3% | H13: 57.6% | I13: +6.3pp | J13: ⚪ STABLE — mall-format dependent
A16: B · REVENUE ₹Cr — Stores→Revenue Same Direction (formula-driven from ⚙️ DATA Block C)
A17: Segment | B17: Metro | C17: T1 | D17: T2 | E17: T3 | F17: T4 | G17: TOTAL | H17: Metro Rev | I17: T3 Rev | J17: T3/Metro
A18: Value Fashion | B18: 6379.8 | C18: 7930.6 | D18: 14804.8 | E18: 11833.9 | F18: 1596.2 | G18: 42545.3 | H18: 6379.8 | I18: 11833.9 | J18: 1.85x
A19: Premium Menswear | B19: 2324 | C19: 1873.3 | D19: 1949 | E19: 691.2 | F19: 161.5 | G19: 6999 | H19: 2324 | I19: 691.2 | J19: 0.30x
A20: Mid Menswear | B20: 598.4 | C20: 756.1 | D20: 1185.1 | E20: 1155.1 | F20: 290.9 | G20: 3985.6 | H20: 598.4 | I20: 1155.1 | J20: 1.93x
A21: Footwear | B21: 2446.3 | C21: 1985 | D21: 2706.9 | E21: 1439.1 | F21: 310.3 | G21: 8887.6 | H21: 2446.3 | I21: 1439.1 | J21: 0.59x
A22: Activewear | B22: 1605.5 | C22: 1074.6 | D22: 961.1 | E22: 304.6 | F22: 92.6 | G22: 4038.4 | H22: 1605.5 | I22: 304.6 | J22: 0.19x
A23: Women's Ethnic | B23: 759.5 | C23: 606.9 | D23: 692.4 | E23: 340.3 | F23: 114.8 | G23: 2513.9 | H23: 759.5 | I23: 340.3 | J23: 0.45x
A24: Women's Western | B24: 467 | C24: 362.7 | D24: 307.1 | E24: 114.1 | F24: 32.9 | G24: 1283.8 | H24: 467 | I24: 114.1 | J24: 0.24x
A25: Multi/Lifestyle | B25: 6730 | C25: 4450 | D25: 5178.9 | E25: 3410.8 | F25: 523.1 | G25: 20292.8 | H25: 6730 | I25: 3410.8 | J25: 0.51x
A28: C · SEGMENT MOAT % — Only 1 Brand in Segment per Pincode
A29: Segment | B29: Metro | C29: T1 | D29: T2 | E29: T3 | F29: T4 | G29: Insight
A30: Value Fashion | B30: 41.4% | C30: 44.3% | D30: 59.0% | E30: 55.5% | F30: 48.6% | G30: High T2 moat (59%) — Trends/Zudio isolation zones
A31: Premium Menswear | B31: 36.0% | C31: 42.1% | D31: 43.3% | E31: 52.2% | F31: 34.1% | G31: T3 moat 52% but total pins low — sat. is Metro story
A32: Mid Menswear | B32: 46.5% | C32: 46.2% | D32: 49.3% | E32: 50.9% | F32: 45.2% | G32: —
A33: Footwear | B33: 36.3% | C33: 46.7% | D33: 55.2% | E33: 55.6% | F33: 57.7% | G33: —
A34: Activewear | B34: 46.4% | C34: 56.5% | D34: 65.3% | E34: 78.6% | F34: 59.1% | G34: T3 moat 79% — Jockey isolation is near total in T3
A35: Women's Ethnic | B35: 35.6% | C35: 39.9% | D35: 50.2% | E35: 60.4% | F35: 54.2% | G35: —
A36: Women's Western | B36: 71.6% | C36: 80.3% | D36: 77.8% | E36: 86.3% | F36: 38.5% | G36: T3 moat 86% — almost every T3 WW pin has only 1 brand
A37: Multi/Lifestyle | B37: 59.0% | C37: 68.2% | D37: 82.1% | E37: 90.6% | F37: 70.3% | G37: —

Sheet EX-16 City Saturation
A1: EX-16 METRO + T1 CITY SATURATION — Which Cities Are Most Crowded?
A2: Noida=21.3 SPP. Indore=20.7. Delhi=19.1. Lucknow=18.7. These are saturated. Patna=5.1 — still wide open.
A4: METRO CITIES
A5: City | B5: Tier | C5: Stores | D5: Active Pins | E5: Brands | F5: SPP | G5: Revenue (₹Cr) | H5: Rev/Pin | I5: Status
A6: Noida | B6: Metro | C6: 359 | D6: 17 | E6: 86 | F6: 21.12 | G6: 1042.2 | H6: 61.3 | I6: ⛔ SAT
A7: Delhi | B7: Metro | C7: 1365 | D7: 72 | E7: 91 | F7: 18.96 | G7: 2977.2 | H7: 41.4 | I7: ⛔ SAT
A8: Gurgaon | B8: Metro | C8: 436 | D8: 24 | E8: 90 | F8: 18.17 | G8: 1351.2 | H8: 56.3 | I8: ⛔ SAT
A9: Faridabad | B9: Metro | C9: 132 | D9: 8 | E9: 62 | F9: 16.5 | G9: 342 | H9: 42.7 | I9: 🔴 HIGH
A10: Thane | B10: Metro | C10: 525 | D10: 32 | E10: 81 | F10: 16.41 | G10: 1275.7 | H10: 39.9 | I10: 🔴 HIGH
A11: Bengaluru | B11: Metro | C11: 1735 | D11: 110 | E11: 94 | F11: 15.77 | G11: 4951.1 | H11: 45 | I11: 🔴 HIGH
A12: Ghaziabad | B12: Metro | C12: 288 | D12: 21 | E12: 66 | F12: 13.71 | G12: 688 | H12: 32.8 | I12: 🔴 HIGH
A13: Mumbai | B13: Metro | C13: 831 | D13: 62 | E13: 86 | F13: 13.4 | G13: 2248 | H13: 36.3 | I13: 🔴 HIGH
A14: Pune | B14: Metro | C14: 775 | D14: 63 | E14: 95 | F14: 12.3 | G14: 1967.9 | H14: 31.2 | I14: 🔴 HIGH
A15: Ahmedabad | B15: Metro | C15: 581 | D15: 48 | E15: 90 | F15: 12.1 | G15: 1437.1 | H15: 29.9 | I15: 🔴 HIGH
A16: Kolkata | B16: Metro | C16: 975 | D16: 154 | E16: 83 | F16: 6.33 | G16: 3030.3 | H16: 19.7 | I16: 🟢 OPEN
A18: T1 CITIES
A19: City | B19: Tier | C19: Stores | D19: Active Pins | E19: Brands | F19: SPP | G19: Revenue (₹Cr) | H19: Rev/Pin | I19: Status
A20: Indore | B20: T1 | C20: 307 | D20: 15 | E20: 86 | F20: 20.47 | G20: 683.4 | H20: 45.6 | I20: ⛔ SAT
A21: Lucknow | B21: T1 | C21: 632 | D21: 34 | E21: 94 | F21: 18.59 | G21: 1575.2 | H21: 46.3 | I21: ⛔ SAT
A22: Kota | B22: T1 | C22: 98 | D22: 7 | E22: 54 | F22: 14 | G22: 185.6 | H22: 26.5 | I22: 🔴 HIGH
A23: Puducherry | B23: T1 | C23: 84 | D23: 6 | E23: 37 | F23: 14 | G23: 159.9 | H23: 26.7 | I23: 🔴 HIGH
A24: Agra | B24: T1 | C24: 94 | D24: 7 | E24: 47 | F24: 13.43 | G24: 211.6 | H24: 30.2 | I24: 🔴 HIGH
A25: Surat | B25: T1 | C25: 273 | D25: 21 | E25: 79 | F25: 13 | G25: 675.8 | H25: 32.2 | I25: 🔴 HIGH
A26: Jaipur | B26: T1 | C26: 493 | D26: 38 | E26: 82 | F26: 12.97 | G26: 1173.2 | H26: 30.9 | I26: 🔴 HIGH
A27: Chandigarh | B27: T1 | C27: 450 | D27: 35 | E27: 79 | F27: 12.86 | G27: 1050.1 | H27: 30 | I27: 🔴 HIGH
A28: Dehra Dun | B28: T1 | C28: 305 | D28: 24 | E28: 85 | F28: 12.71 | G28: 747.1 | H28: 31.1 | I28: 🔴 HIGH
A29: Hyderabad | B29: T1 | C29: 1246 | D29: 100 | E29: 92 | F29: 12.46 | G29: 3437.5 | H29: 34.4 | I29: 🔴 HIGH
A30: Patna | B30: T1 | C30: 468 | D30: 40 | E30: 77 | F30: 11.7 | G30: 1241.8 | H30: 31 | I30: 🟡 MID
A31: Varanasi | B31: T1 | C31: 198 | D31: 18 | E31: 62 | F31: 11 | G31: 494.3 | H31: 27.5 | I31: 🟡 MID
... A42: Mysore | B42: T1 | C42: 230 | D42: 39 | E42: 60 | F42: 5.9 | G42: 829.5 | H42: 21.3 | I42: 🟢 OPEN

Sheet EX-17 Ethnic Wear
A1: EX-17 WOMEN'S ETHNIC WEAR — 11 Brands, 2,087 Stores, Metro Fortress
A2: 74.3% of ethnic stores are in Metro+T1. T3 has 196 stores for 700Mn people. Organised ethnic barely exists below T1.
A4: Rank | B4: Brand | C4: Metro | D4: T1 | E4: T2 | F4: T3 | G4: T4 | H4: Total | I4: Metro+T1% | J4: Rev FY26 | K4: Rev/Store | L4: Signal
A5: 1 | B5: Biba | C5: 123 | D5: 111 | E5: 104 | F5: 29 | G5: 3 | H5: 370 | I5: 63.2% | J5: 381 | K5: 1.03 | L5: ⚪ T2 Trans.
A6: 2 | B6: FabIndia | C6: 147 | D6: 85 | E6: 82 | F6: 25 | G6: 11 | H6: 350 | I6: 66.3% | J6: 1060 | K6: 3.03 | L6: 🟡 Mostly Metro
A7: 3 | B7: Manyawar | C7: 84 | D7: 69 | E7: 87 | F7: 47 | G7: 17 | H7: 304 | I7: 50.3% | J7: 1667 | K7: 5.48 | L7: ⚪ T2 Trans.
A8: 4 | B8: W for Woman | C8: 78 | D8: 73 | E8: 87 | F8: 36 | G8: 7 | H8: 281 | I8: 53.7% | J8: 331 | K8: 1.18 | L8: ⚪ T2 Trans.
A9: 5 | B9: Aurelia | C9: 66 | D9: 60 | E9: 72 | F9: 32 | G9: 9 | H9: 239 | I9: 52.7% | J9: 246 | K9: 1.03 | L9: ⚪ T2 Trans.
A10: 6 | B10: Mohey | C10: 56 | D10: 53 | E10: 38 | F10: 21 | G10: 2 | H10: 170 | I10: 64.1% | J10: 221 | K10: 1.3 | L10: ⚪ T2 Trans.
A11: 7 | B11: Soch | C11: 58 | D11: 52 | E11: 50 | F11: 3 | G11: 2 | H11: 165 | I11: 66.7% | J11: 220 | K11: 1.33 | L11: 🟡 Mostly Metro
A12: 8 | B12: Tasva | C12: 47 | D12: 30 | E12: 10 | F12: 1 | G12: 0 | H12: 88 | I12: 87.5% | J12: 100 | K12: 0 | L12: 🔴 Metro Captive
A13: 9 | B13: Libas | C13: 35 | D13: 7 | E13: 6 | F13: 0 | G13: 0 | H13: 48 | I13: 87.5% | J13: 162 | K13: 3.38 | L13: 🔴 Metro Captive
A14: 10 | B14: Ritu Kumar | C14: 21 | D14: 16 | E14: 8 | F14: 1 | G14: 1 | H14: 47 | I14: 78.7% | J14: 191 | K14: 4.06 | L14: 🟡 Mostly Metro
A15: 11 | B15: Global Desi | C15: 17 | D15: 5 | E15: 2 | F15: 1 | G15: 0 | H15: 25 | I15: 88.0% | J15: 79 | K15: 3.16 | L15: 🔴 Metro Captive
A16: — | B16: TOTAL | C16: 732 | D16: 561 | E16: 546 | F16: 196 | G16: 52 | H16: 2087 | I16: 62.0%
A18: ETHNIC WEAR WHITESPACE — THE INVESTOR SIGNAL
A19: Metric | B19: Value | C19: Context
A20: Organised ethnic stores in T3 | B20: 196 stores | C20: 322 districts — avg 0.6 stores/district
A21: T3 organised ethnic revenue | B21: ₹340 Cr | C21: Metro = ₹759 Cr — 2.2× higher despite far fewer districts
A22: Top T3 ethnic brands | B22: FabIndia, Biba, Manyawar | C22: Combined T3 stores = 105 across 322 districts
A23: T3 organised ethnic share of wallet | B23: <0.5% | C23: ₹65,000 Cr+ T3 women's ethnic spend is unorganised
A24: Implied T3 opportunity (T2 parity) | B24: 1,500+ ethnic stores | C24: T2 has 546 across 246 districts — T3 should have ~800

Sheet EX-18 Moat Pincodes
A1: EX-18 MOAT PINCODE ANALYSIS — Single-Brand Segment Dominance | 1,356 Moat Pincodes
A2: Reliance Trends=792 VF moat pins. Jockey=706 Activewear. Zudio=182 VF moat (23.5% Zudio-only). Revenue moats are structural.
A4: PINCODE COMPETITION LANDSCAPE — All 3,922 Active Pincodes
A5: Category | B5: Total Pincodes | C5: Revenue (₹Cr) | D5: Metro | E5: T1 | F5: T2 | G5: T3 | H5: T4 | I5: Signal
A6: Moat (1 brand) | B6: 1363 | C6: 7885 | D6: 132 | E6: 190 | F6: 563 | G6: 429 | H6: 49 | I6: Single-brand dominance — structural margin protection
A7: Lightly (2-4) | B7: 1174 | C7: 13464 | D7: 162 | E7: 196 | F7: 444 | G7: 329 | H7: 43 | I7: Nascent — first 2 brands win outsized share
A8: Competitive (5-9) | B8: 611 | C8: 13631 | D8: 118 | E8: 128 | F8: 199 | G8: 144 | H8: 22 | I8: Healthy — full format mix arriving
A9: Crowded (10-19) | B9: 440 | C9: 18282 | D9: 99 | E9: 74 | F9: 126 | G9: 129 | H9: 12 | I9: Margin pressure — share gains are zero-sum
A10: Saturated (20+) | B10: 342 | C10: 37284 | D10: 100 | E10: 90 | F10: 97 | G10: 41 | H10: 14 | I10: Value destruction zone — avoid for greenfield
A13: TOP BRAND MOAT PINCODES — Segment-Level Dominance + Revenue
A14: Rank | B14: Brand | C14: Segment | D14: Moat Pins | E14: Rev FY26 | F14: Rev/Store | G14: Revenue Signal
A15: 1 | B15: Reliance Trends | C15: Value Fashion | D15: 792 | E15: 21200 | F15: 10 | G15: 792 VF moat — widest organised apparel moat
A16: 2 | B16: Jockey | C16: Activewear | D16: 706 | E16: 1022 | F16: 0.65 | G16: 706 Activewear — monopoly on T3 athleisure
A17: 3 | B17: Reliance Smart Bazaar | C17: Multi/Lifestyle | D17: 658 | E17: 11143 | F17: 11 | G17: 658 Multi/Lifestyle — RSB dominates format wherever it opens
A18: 4 | B18: Bata | C18: Footwear | D18: 552 | E18: 1551 | F18: 0.85 | G18: 552 Footwear — Bata is the only organised shoe in 552 pincodes
A19: 5 | B19: Go Colors | C19: Women's Western | D19: 473 | E19: 609 | F19: 0.76 | G19: 473 Women's Western — Go Colors unchallenged in T2/T3 WW
A20: 6 | B20: Raymond | C20: Premium Menswear | D20: 337 | E20: 1284 | F20: 0.95 | G20: 337 Premium — sole premium brand in 337 pincodes
A21: 7 | B21: Peter England | C21: Mid Menswear | D21: 206 | E21: 0 | F21: 0 | G21: 206 pincodes where Peter_England_ is only Mid Menswear brand
A22: 8 | B22: Zudio | C22: Value Fashion | D22: 182 | E22: 8148 | F22: 8.46 | G22: 182 VF moat — 23.5% of Zudio pins have zero VF competition
A23: 9 | B23: Vishal Mega Mart | C23: Value Fashion | D23: 179 | E23: 5419 | F23: 6.82 | G23: 179 pincodes where Vishal_Mega_Mart is only Value Fashion brand
A24: 10 | B24: Killerjeans | C24: Mid Menswear | D24: 131 | E24: 0 | F24: 0 | G24: 131 pincodes where Killerjeans is only Mid Menswear brand
A25: 11 | B25: Pantaloons | C25: Multi/Lifestyle | D25: 122 | E25: 4247 | F25: 10.64 | G25: 122 pincodes where Pantaloons is only Multi/Lifestyle brand
A26: 12 | B26: Cantabil | C26: Mid Menswear | D26: 102 | E26: 801 | F26: 1.23 | G26: 102 pincodes where Cantabil is only Mid Menswear brand
... A34: 20 | B34: Siyarams | C34: Mid Menswear | D34: 51 | E34: 2158 | F34: 9.34 | G34: 51 pincodes where Siyarams is only Mid Menswear brand
A36: ZUDIO COMPETITIVE ISOLATION — The Revenue Moat Metric
A37: Metric | B37: Value | C37: Investor Read
A38: Zudio total VF pincodes | B38: 776 | C38: 217 Metro | 181 T1 | 225 T2 | 263 T3 | 21 T4
A39: Zudio-only (no other VF brand) | B39: 182 pincodes (23.5%) | C39: In these 182, Zudio faces ZERO organised VF competition
A40: Metro: Zudio-only | B40: 64 pins (29.5% of Zudio Metro) | C40: High isolation even in metros — premium micro-markets
A41: T2: Zudio-only | B41: 56 pins (24.9% of Zudio T2) | C41: Highest TAM moat — T2 wallet is largest in absolute ₹
A42: T3: Zudio-only | B42: 35 pins (13.3% of Zudio T3) | C42: T3 VF market is relatively contested — Trends, V-Mart too
A43: Zudio FY26 Revenue | B43: ₹8,148 Cr | C43: ₹8.46 Cr/store × 963 stores — source: Trent AR FY25
A44: Revenue in moat pincodes (est) | B44: ₹1,540 Cr | C44: 182 pins × 1.5 stores × ₹8.46 Cr — competitor-free revenue

Sheet EX-19 Store Potential
A1: EX-19 STORE POTENTIAL MODEL — Density Runway + Revenue Upside
A2: T3 density uplift = 1,410 stores. Greenfield (20% zero pins) = 917 stores. Total: 2,327 new T3 stores → ₹4,654 Cr revenue.
A4: ASSUMPTIONS
A5: Parameter | B5: Value | C5: Rationale
A6: Target Density (Benchmark) | B6: T2 level = 6.66 stores/active pin | C6: Proven sustainable density, not saturation
A7: Avg Revenue/New Store | B7: ₹2.0 Cr/year | C7: Conservative; actual T3 leader avg is ₹3-5 Cr
A8: Greenfield Conversion | B8: 20% of zero-pincodes activate in 5 years | C8: Grad ramp; T3 closer to 10-15%, T2 to 25-30%
A9: Runway Basis | B9: Density uplift + greenfield (separate tracks) | C9: Different conversion assumptions per track
A12: STORE POTENTIAL BY TIER (formula: Density Col × Active Pins − Current Stores)
A13: Tier | B13: Current Stores | C13: Active Pins | D13: Zero Pins | E13: Current SPP | F13: Target SPP | G13: Density Runway | H13: Greenfield | I13: Total Runway | J13: Revenue Upside (₹Cr) | K13: Priority
A14: ='⚙️ DATA'!A5 | B14: 8002 | C14: 611 | D14: 0 | E14: 13.1 | F14: — | G14: 0 | H14: 0 | I14: 0 | J14: 0 | K14: SATURATED — refurbish, not expand
A15: ='⚙️ DATA'!A6 | B15: 7340 | C15: 680 | D15: 0 | E15: 10.79 | F15: — | G15: 0 | H15: 0 | I15: 0 | J15: 0 | K15: FULL — selective premium only
A16: ='⚙️ DATA'!A7 | B16: 9518 | C16: 1428 | D16: 0 | E16: 6.67 | F16: — | G16: 0 | H16: 0 | I16: 0 | J16: 0 | K16: AT BENCHMARK — zero-pin greenfield
A17: ='⚙️ DATA'!A8 | B17: 5963 | C17: 1072 | D17: 0 | E17: 5.56 | F17: 6.66 | G17: 1179 | H17: 0 | I17: 1179 | J17: 2358 | K17: 🟢 PRIMARY TARGET — density + greenfield
A18: ='⚙️ DATA'!A9 | B18: 990 | C18: 140 | D18: 0 | E18: 7.07 | F18: 6.66 | G18: 0 | H18: 0 | I18: 0 | J18: 0 | K18: 🟡 NICHE — selective micro-markets
A21: ZUDIO STORE POTENTIAL — Pincode-by-Pincode Revenue Validation
A22: Metric | B22: Value | C22: Context
A23: Zudio T2 runway | B23: 1,204 pincodes | C23: 79.4% of T2 active pincodes have no Zudio
A24: Zudio T3 runway | B24: 931 pincodes | C24: 87.5% of T3 active pincodes have no Zudio
A25: Total T2+T3 addressable | B25: 2,135 pincodes | C25: =3,202 new stores at 1.5 stores/pin
A26: Revenue upside (₹8.46/store) | B26: ₹27,100 Cr | C26: Conservative — uses actual FY26 revenue/store
A27: DATA VALIDATES MANAGEMENT | B27: 3,000+ target | C27: Pincode math + revenue math both agree

Sheet EX-20 Brand Dashboards
A1: EX-20 BRAND DASHBOARDS — Zudio · Reliance Trends · Westside · V-Mart
A2: 8-10 key metrics per brand sourced from Brand Financials + Pincode analysis. Which has the most runway?
A4: ZUDIO | Value Fashion | Trent / Tata
A5: FY26 Revenue | B5: FY25 Revenue | C5: Stores (Mar26) | D5: Rev/Store | E5: Store Adds FY26
A6: ₹8,148 Cr | B6: ₹6,432 Cr | C6: 963 | D6: ₹8.46 Cr | E6: 198
A7: Total Pincodes | B7: Metro+T1 Pins | C7: T2+T3+T4 Pins | D7: Moat Pincodes | E7: Store Runway
A8: 776 | B8: 398 | C8: 378 | D8: 182 (23.5%) | E8: 3,200+ stores → ₹27,100 Cr upside
A10: RELIANCE TRENDS | Value Fashion | Reliance Retail
A11: Category | B11: Total Pincodes | C11: Metro+T1 Pins | D11: T2+T3+T4 Pins | E11: VF Moat Pincodes
A12: Value Fashion | B12: 1,768 | C12: 473 | D12: 1,295 | E12: 792 (44.8%)
A13: T2 Pincodes | B13: T3 Pincodes | C13: Rev/Store (est) | D13: Moat Depth | E13: Verdict
A14: 704 | B14: 533 | C14: ₹10 Cr | D14: Widest moat in organised apparel | E14: Multi-Tier Leader — strongest VF distribution
A16: WESTSIDE | Multi/Lifestyle | Trent / Tata
A17: FY26 Revenue | B17: FY25 Revenue | C17: Stores (Mar26) | D17: Rev/Store | E17: Store Adds FY26
A18: ₹8,376 Cr | B18: ₹6,882 Cr | C18: 300 | D18: ₹27.92 Cr | E18: 52
A19: Total Pincodes | B19: Metro+T1 Pins | C19: T2+T3+T4 Pins | D19: Segment | E19: Verdict
A20: 199 | B20: 138 (69.3%) | C20: 61 (30.7%) | D20: Multi/Lifestyle | E20: Metro Fortress — high MPCE focus, limited T2/T3 format fit
A22: V-MART | Value Fashion | V Mart Retail
A23: FY26 Revenue | B23: FY25 Revenue | C23: Stores (Mar26) | D23: Rev/Store | E23: Store Adds FY26
A24: ₹2,532 Cr | B24: ₹2,177 Cr | C24: 478 | D24: ₹5.30 Cr | E24: 66
A25: Total Pincodes | B25: Moat Pincodes (VF) | C25: Focus Tier | D25: Strategy | E25: Verdict
A26: — | B26: 71 | C26: T3 / T4 | D26: Smaller cities, lower MPCE | E26: Tier Pioneer — T3/T4 specialist, building capillary distribution

Sheet EX-21 Pop×Income Paradox
A1: EX-21 POP × INCOME PARADOX — Why Tier Beats State as Investment Variable
A2: Gujarat ranks top-3 income but has massive T3 under-penetration. UP is low-income but Lucknow punches Metro equivalent. The Tier lens resolves this.
A4: State | B4: MPCE Rank | C4: Store Rank | D4: Gap | E4: Tier Explanation
A5: Delhi | B5: #2 | C5: #1 | D5: +1 | E5: Metro-heavy: 72% stores in Metro — income rank matches penetration correctly
A6: Gujarat | B6: #3 | C6: #8 | D6: -5 | E6: High income but outside Ahm./Surat/Vadodara (Metro/T1), T2/T3 barely organised
A7: UP | B7: #10 | C7: #3 | D7: +7 | E7: Low avg MPCE masks Lucknow/Kanpur/Agra — T1 cities punch well above state income avg
A8: Maharashtra | B8: #2 | C8: #2 | D8: 0 | E8: High income + density but Mumbai+Pune = 65% state stores — rest is T3 whitespace
A9: Rajasthan | B9: #7 | C9: #12 | D9: -5 | E9: Mid income but Jaipur saturated; rest (T2/T3) mostly untouched — classic bifurcation
A10: West Bengal | B10: #5 | C10: #9 | D10: -4 | E10: Kolkata=Metro (saturated). Rest of Bengal=T3 low income — completely bifurcated
A11: Kerala | B11: #4 | C11: #15 | D11: -11 | E11: High income but organised apparel LOW — cultural preference for local/unbranded
A12: Karnataka | B12: #3 | C12: #4 | D12: -1 | E12: Bengaluru=Metro. Mysore/Hubli=T2 w/rising income — T2 expansion window open
A15: WHY TIER BEATS STATE — THE RESOLUTION FRAMEWORK
A16: State MPCE masks tier distribution | B16: Gujarat's ₹3,200 MPCE average is dragged up by Ahmedabad (₹8,000+) and down by rural Saurashtra (₹1,500). A state-level filter misses both the opportunity AND the risk. The same issue exists in every large state.
A17: Tier classification captures retail readiness | B17: A T2 city in low-MPCE UP (e.g. Bareilly) may have more organised apparel wallet than rural T3 Gujarat. Tier proxies for urban density, aspirational spending, and supply chain viability simultaneously — which state MPCE cannot.
A18: The Lucknow anomaly (UP) | B18: UP ranks bottom-5 in state MPCE. But Lucknow (T1) has 636 stores at 18.7 stores/active pin — nearly Metro equivalent. The city is richer and more brand-aware than its state average suggests. Tier captures this; state doesn't.
A19: The Gujarat-Ahmedabad paradox | B19: Gujarat ranks top-3 in state MPCE. But outside Ahmedabad, Surat, and Vadodara (Metro/T1), T2/T3 districts have very few organised stores and large revenue gaps. High state income ≠ T3 organised readiness — city-tier matters more.

Sheet ⚙️ DATA
A1: ⚙️ DATA — Master Source Table | Update here → all exhibits auto-refresh via formulas
A3: A — TIER SUMMARY
A4: Tier | B4: Label | C4: Stores | D4: Revenue_Cr | E4: Active_Pins | F4: SPP | G4: Rev_per_Store | H4: Rev_per_Pin | I4: Stores_%
A5: Metro | B5: Mega Metro | C5: 8002 | D5: 21310.5 | E5: 611 | F5: 13.1 | G5: 2.66 | H5: 34.88 | I5: =C5/C10
A6: T1 | B6: Tier 1 City | C6: 7340 | D6: 19039.1 | E6: 679 | F6: 10.81 | G6: 2.59 | H6: 28.04 | I6: =C6/C10
A7: T2 | B7: Tier 2 City | C7: 9518 | D7: 27785.4 | E7: 1429 | F7: 6.66 | G7: 2.92 | H7: 19.44 | I7: =C7/C10
A8: T3 | B8: Tier 3 Town | C8: 5963 | D8: 19289.1 | E8: 1285 | F8: 4.64 | G8: 3.23 | H8: 15.01 | I8: =C8/C10
A9: T4 | B9: Tier 4 Micro | C9: 990 | D9: 3122.2 | E9: 140 | F9: 7.07 | G9: 3.15 | H9: 22.3 | I9: =C9/C10
A10: TOTAL | B10: All India | C10: =SUM(C5:C9) | D10: =SUM(D5:D9) | E10: =SUM(E5:E9) | F10: =C10/E10 | G10: =D10/C10 | H10: =D10/E10 | I10: 100.0%
A12: B — STORES by Tier × Segment
A13: Tier | B13: Value Fashion | C13: Premium Menswear | D13: Mid Menswear | E13: Footwear | F13: Activewear | G13: Women's Ethnic | H13: Women's Western | I13: Multi/Lifestyle | J13: TOTAL
A14: Metro | B14: 1234 | C14: 1867 | D14: 835 | E14: 1400 | F14: 953 | G14: 732 | H14: 467 | I14: 514 | J14: =SUM(B14:I14)
A15: T1 | B15: 1403 | C15: 1672 | D15: 867 | E15: 1171 | F15: 880 | G15: 561 | H15: 379 | I15: 407 | J15: =SUM(B15:I15)
A16: T2 | B16: 2269 | C16: 1946 | D16: 1337 | E16: 1563 | F16: 981 | G16: 546 | H16: 329 | I16: 547 | J16: =SUM(B16:I16)
A17: T3 | B17: 1751 | C17: 837 | D17: 981 | E17: 945 | F17: 479 | G17: 196 | H17: 123 | I17: 651 | J17: =SUM(B17:I17)
A18: T4 | B18: 250 | C18: 153 | D18: 178 | E18: 180 | F18: 92 | G18: 52 | H18: 30 | I18: 55 | J18: =SUM(B18:I18)
A19: TOTAL | B19: =SUM(B14:B18) | C19: =SUM(C14:C18) | D19: =SUM(D14:D18) | E19: =SUM(E14:E18) | F19: =SUM(F14:F18) | G19: =SUM(G14:G18) | H19: =SUM(H14:H18) | I19: =SUM(I14:I18) | J19: =SUM(J14:J18)
A21: C — REVENUE by Tier × Segment (₹ Cr)
A22: Tier | B22: Value Fashion | C22: Premium Menswear | D22: Mid Menswear | E22: Footwear | F22: Activewear | G22: Women's Ethnic | H22: Women's Western | I22: Multi/Lifestyle | J22: TOTAL
A23: Metro | B23: 6379.8 | C23: 2324 | D23: 598.4 | E23: 2446.3 | F23: 1605.5 | G23: 759.5 | H23: 467 | I23: 6730 | J23: =SUM(B23:I23)
A24: T1 | B24: 7930.6 | C24: 1873.3 | D24: 756.1 | E24: 1985 | F24: 1074.6 | G24: 606.9 | H24: 362.7 | I24: 4450 | J24: =SUM(B24:I24)
A25: T2 | B25: 14804.8 | C25: 1949 | D25: 1185.1 | E25: 2706.9 | F25: 961.1 | G25: 692.4 | H25: 307.1 | I25: 5178.9 | J25: =SUM(B25:I25)
A26: T3 | B26: 11833.9 | C26: 691.2 | D26: 1155.1 | E26: 1439.1 | F26: 304.6 | G26: 340.3 | H26: 114.1 | I26: 3410.8 | J26: =SUM(B26:I26)
A27: T4 | B27: 1596.2 | C27: 161.5 | D27: 290.9 | E27: 310.3 | F27: 92.6 | G27: 114.8 | H27: 32.9 | I27: 523.1 | J27: =SUM(B27:I27)
A28: TOTAL | B28: =SUM(B23:B27) | C28: =SUM(C23:C27) | D28: =SUM(D23:D27) | E28: =SUM(E23:E27) | F28: =SUM(F23:F27) | G28: =SUM(G23:G27) | H28: =SUM(H23:H27) | I28: =SUM(I23:I27) | J28: =SUM(J23:J27)
A30: D — SEGMENT % WITHIN TIER (formulas → Block B)
A31: Tier | B31: Value Fashion | C31: Premium Menswear | D31: Mid Menswear | E31: Footwear | F31: Activewear | G31: Women's Ethnic | H31: Women's Western | I31: Multi/Lifestyle
A32: Metro | B32: =IF(J14=0,0,B14/J14) | C32: =IF(J14=0,0,C14/J14) | D32: =IF(J14=0,0,D14/J14) | E32: =IF(J14=0,0,E14/J14) | F32: =IF(J14=0,0,F14/J14) | G32: =IF(J14=0,0,G14/J14) | H32: =IF(J14=0,0,H14/J14) | I32: =IF(J14=0,0,I14/J14)
A33: T1 | B33: =IF(J15=0,0,B15/J15) | C33: =IF(J15=0,0,C15/J15) | D33: =IF(J15=0,0,D15/J15) | E33: =IF(J15=0,0,E15/J15) | F33: =IF(J15=0,0,F15/J15) | G33: =IF(J15=0,0,G15/J15) | H33: =IF(J15=0,0,H15/J15) | I33: =IF(J15=0,0,I15/J15)
A34: T2 | B34: =IF(J16=0,0,B16/J16) | C34: =IF(J16=0,0,C16/J16) | D34: =IF(J16=0,0,D16/J16) | E34: =IF(J16=0,0,E16/J16) | F34: =IF(J16=0,0,F16/J16) | G34: =IF(J16=0,0,G16/J16) | H34: =IF(J16=0,0,H16/J16) | I34: =IF(J16=0,0,I16/J16)
A35: T3 | B35: =IF(J17=0,0,B17/J17) | C35: =IF(J17=0,0,C17/J17) | D35: =IF(J17=0,0,D17/J17) | E35: =IF(J17=0,0,E17/J17) | F35: =IF(J17=0,0,F17/J17) | G35: =IF(J17=0,0,G17/J17) | H35: =IF(J17=0,0,H17/J17) | I35: =IF(J17=0,0,I17/J17)
A36: T4 | B36: =IF(J18=0,0,B18/J18) | C36: =IF(J18=0,0,C18/J18) | D36: =IF(J18=0,0,D18/J18) | E36: =IF(J18=0,0,E18/J18) | F36: =IF(J18=0,0,F18/J18) | G36: =IF(J18=0,0,G18/J18) | H36: =IF(J18=0,0,H18/J18) | I36: =IF(J18=0,0,I18/J18)
A38: E — BRAND FINANCIALS (FY25/26 actual — update here to refresh exhibits)
A39: Brand | B39: Segment | C39: Rev FY26 | D39: Rev FY25 | E39: Stores Mar26 | F39: Rev/Store | G39: Store Adds FY25 | H39: Store Adds FY26 | I39: Metro Pins | J39: T1 Pins | K39: T2 Pins | L39: T3 Pins
A40: Reliance_Trends | B40: Value Fashion | C40: 21200 | D40: 0 | E40: 0 | F40: 10 | G40: 2022 | H40: 22526 | I40: 192 | J40: 281 | K40: 704 | L40: 532
A41: Zudio | B41: Value Fashion | C41: 11768.88 | D41: 7597.7 | E41: 3141 | F41: 0 | G41: 0 | H41: 0 | I41: 217 | J41: 181 | K41: 225 | L41: 132
A42: Westside | B42: Multi/Lifestyle | C42: 11768.88 | D42: 7597.7 | E42: 3141 | F42: 0 | G42: 0 | H42: 0 | I42: 9 | J42: 0 | K42: 1 | L42: 236
A43: Reliance_Smart_Bazaar | B43: Multi/Lifestyle | C43: 11143 | D43: 0 | E43: 0 | F43: 11 | G43: 0 | H43: 0 | I43: 141 | J43: 151 | K43: 313 | L43: 274
A44: Lifestyle | B44: Multi/Lifestyle | C44: 11083 | D44: 11573 | E44: 9133 | F44: 0 | G44: 43 | H44: 0 | I44: 47 | J44: 40 | K44: 29 | L44: 4
A45: Westside | B45: Multi/Lifestyle | C45: 8376 | D45: 6882 | E45: 300 | F45: 27.92 | G45: 16 | H45: 52 | I45: 9 | J45: 0 | K45: 1 | L45: 236
...
